Workbook

Sheet Graph
A3: Month | B3: Net | C3: Checking | D3: Savings | E3: Investment | F3: Change % MoM | G3: Change % YoY | I3: Category | J3: 2014 | K3: 2015 | L3: 2016 | M3: 2017 | N3: 2018 | O3: 2019 | P3: 2020 | Q3: 2021 | R3: 2022 | S3: 2023 | T3: 2024 | U3: 2025 | V3: 2026
A4: 41640 | B4: 21649.025 | C4: 1271.79 | D4: 10006.255 | E4: 10370.98 | F4: 0 | I4: Cable | J4: 851.91 | K4: 987.32 | L4: 1197.49 | M4: 1543.82 | N4: 2034.95 | O4: 1970.25 | P4: 3356.2 | Q4: 3292.78 | R4: 3440.28 | S4: 2037.2 | T4: 3993.94 | U4: 4846.57 | V4: =ABS(Summary!F21) -> 1782.99
A5: 41671 | B5: 22401.335 | C5: 1297.42 | D5: 9951.605 | E5: 11152.31 | F5: =(B5-B4)/B4 -> 0.034750295 | I5: Car Insurance | J5: 927.31 | K5: 495.81 | L5: 664 | M5: 725.62 | N5: 806.4 | O5: 862.29 | P5: 812.38 | Q5: 1736.44 | R5: 1845.05 | S5: 2349.59 | T5: 4515 | U5: 4026.47 | V5: =ABS(Summary!F22) -> 1726.67
A6: 41699 | B6: 23723.73 | C6: 1345.88 | D6: 10747.5 | E6: 11630.35 | F6: =(B6-B5)/B5 -> 0.059031973 | I6: Cleaners | J6: 96.56 | K6: 91 | L6: 20 | M6: 0 | N6: 0 | O6: 0 | P6: 0 | Q6: 0 | R6: 0 | S6: 0 | T6: 0 | U6: 0 | V6: =ABS(Summary!F23) -> 0
A7: 41730 | B7: 23432.04 | C7: 1400 | D7: 10273.68 | E7: 11758.36 | F7: =(B7-B6)/B6 -> -0.012295284 | I7: Clothes | J7: 1332.7 | K7: 116.71 | L7: 258.73 | M7: 819.96 | N7: 557.72 | O7: 317 | P7: 322 | Q7: 709 | R7: 883 | S7: 1865.7 | T7: 3446.48 | U7: 3322.58 | V7: =ABS(Summary!F24) -> 1827.19
A8: 41760 | B8: 24523.49 | C8: 1450.97 | D8: 10694.02 | E8: 12378.5 | F8: =(B8-B7)/B7 -> 0.046579384 | I8: Utilities | J8: 0 | K8: 0 | L8: 0 | M8: 0 | N8: 0 | O8: 0 | P8: 0 | Q8: 277.75 | R8: 4044.92 | S8: 7082.98 | T8: 8422.68 | U8: 8054.25 | V8: =ABS(Summary!F25) -> 3543.06
A9: 41791 | B9: 24628.91 | C9: 1500.93 | D9: 10109.97 | E9: 13018.01 | F9: =(B9-B8)/B8 -> 0.0042987356 | I9: Dining | J9: 7007.295 | K9: 4867.59 | L9: 7576.94 | M9: 9145.189 | N9: 7811.36 | O9: 9042.62 | P9: 7226.48 | Q9: 6448.99 | R9: 10189.09 | S9: 15350.63 | T9: 16817.09 | U9: 18139.49 | V9: =ABS(Summary!F26) -> 8682.83
A10: 41821 | B10: 25890.34 | C10: 1550.26 | D10: 11063.67 | E10: 13276.41 | F10: =(B10-B9)/B9 -> 0.051217451 | I10: Entertainment | J10: 589.01 | K10: 1280.43 | L10: 2038.2 | M10: 3337.86 | N10: 2322 | O10: 3807.97 | P10: 2895.82 | Q10: 2035.44 | R10: 3210.96 | S10: 2512 | T10: 4405 | U10: 4789.02 | V10: =ABS(Summary!F27) -> 2548.38
A11: 41852 | B11: 26583.16 | C11: 1600.44 | D11: 11204.09 | E11: 13778.63 | F11: =(B11-B10)/B10 -> 0.026759788 | I11: Gas | J11: 2440.2405 | K11: 1967.55 | L11: 2032.52 | M11: 2661.15 | N11: 2767.39 | O11: 2393.93 | P11: 1819.54 | Q11: 3552.42 | R11: 5292.16 | S11: 2735.74 | T11: 2230.68 | U11: 2605.1 | V11: =ABS(Summary!F28) -> 1491.94
A12: 41883 | B12: 27276.63 | C12: 1650 | D12: 10319.13 | E12: 15307.5 | F12: =(B12-B11)/B11 -> 0.026086816 | I12: Gifts | J12: 431.16 | K12: 1026.8 | L12: 320 | M12: 1446.25 | N12: 1912 | O12: 2816.02 | P12: 4201.05 | Q12: 2303.89 | R12: 4561.3 | S12: 4085.81 | T12: 7078.06 | U12: 3429 | V12: =ABS(Summary!F29) -> 2699.84
A13: 41913 | B13: 27004.21 | C13: 1650.49 | D13: 9804.71 | E13: 15549.01 | F13: =(B13-B12)/B12 -> -0.0099873042 | I13: Grocery | J13: 622.87 | K13: 844.37 | L13: 1296.999 | M13: 2195.06 | N13: 1338.21 | O13: 4714.05 | P13: 4736.63 | Q13: 5762.05 | R13: 9675.2 | S13: 11091.32 | T13: 14672.91 | U13: 13428.26 | V13: =ABS(Summary!F30) -> 4870.26
A14: 41944 | B14: 26880.92 | C14: 1700 | D14: 9288.45 | E14: 15892.47 | F14: =(B14-B13)/B13 -> -0.0045655844 | I14: Gym | J14: 275.93 | K14: 0 | L14: 525.21 | M14: 1035.99 | N14: 1092 | O14: 1135.78 | P14: 585.66 | Q14: 1449.76 | R14: 2210.21 | S14: 1559 | T14: 2664.8 | U14: 1858 | V14: =ABS(Summary!F31) -> 359
A15: 41974 | B15: 27223.75 | C15: 1750 | D15: 9370.99 | E15: 16102.76 | F15: =(B15-B14)/B14 -> 0.012753656 | G15: =(B15-B4)/B4 -> 0.25750467 | I15: Loan | J15: 10860.31 | K15: 8088.87 | L15: 3286.78 | M15: 0 | N15: 0 | O15: 0 | P15: 0 | Q15: 0 | R15: 0 | S15: 3042 | T15: 0 | U15: 0 | V15: =ABS(Summary!F32) -> 0
A16: 42005 | B16: 28593.49 | C16: 1800.15 | D16: 9866.77 | E16: 16426.57 | F16: =(B16-B15)/B15 -> 0.050314156 | I16: Misc | J16: 2230.39 | K16: 2452.72 | L16: 1760.55 | M16: 2736.42 | N16: 5846.81 | O16: 7540.08 | P16: 3321.9 | Q16: 5192.64 | R16: 10567.66 | S16: 15194.14 | T16: 8684.53 | U16: 8066.38 | V16: =ABS(Summary!F33) -> 2080
A17: 42036 | B17: 28220.99 | C17: 1850.06 | D17: 8868.08 | E17: 17002.85 | F17: =(B17-B16)/B16 -> -0.013027441 | I17: Offering | J17: 785.92 | K17: =481.36+456 -> 937.36 | L17: 878.05 | M17: 1666.15 | N17: 1440 | O17: 1552.64 | P17: 1817 | Q17: 1402.21 | R17: 2129 | S17: 4066 | T17: 5273 | U17: 8410 | V17: =ABS(Summary!F34) -> 4955.54
A18: 42064 | B18: 28589.92 | C18: 1900 | D18: 8800.08 | E18: 17584.84 | F18: =(B18-B17)/B17 -> 0.013072894 | I18: Rent | J18: 6436.94 | K18: 10040.33 | L18: 8503.97 | M18: 8283.08 | N18: 11107.76 | O18: 9917.18 | P18: 16928.247 | Q18: 10437.13 | R18: 33954.52 | S18: 36146.49 | T18: 50666 | U18: 48773 | V18: =ABS(Summary!F35) -> 25304
A19: 42095 | B19: 29266.99 | C19: 1900 | D19: 9110.4 | E19: 17951.05 | F19: =(B19-B18)/B18 -> 0.023682123 | I19: Travel | J19: 472.98 | K19: 345.32 | L19: 1280.54 | M19: 1057.97 | N19: 5707.71 | O19: 6035.42 | P19: 816 | Q19: 10424.68 | R19: 10431 | S19: 11718.75 | T19: 13939 | U19: 4603.3 | V19: =ABS(Summary!F36) -> 5677
A20: 42125 | B20: 30007.84 | C20: 1950 | D20: 9359.4 | E20: 18342.9 | F20: =(B20-B19)/B19 -> 0.025313502 | I20: Parents | J20: 0 | K20: 0 | L20: 1153.27 | M20: 1769.96 | N20: 3186.91 | O20: 2725.69 | P20: 2409.61 | Q20: 4132.62 | R20: 1959 | S20: 4032 | T20: 8401 | U20: 9116 | V20: =ABS(Summary!F37) -> 3045
A21: 42156 | B21: 30396.9 | C21: 1969.8 | D21: 9478.2 | E21: 18668.9 | F21: =(B21-B20)/B20 -> 0.012965278 | I21: Car | J21: 37.82 | K21: 267.82 | L21: 537.04 | M21: 262 | N21: 612 | O21: 266.51 | P21: 10393 | Q21: 4361.26 | R21: 3532 | S21: 3311 | T21: 1793 | U21: 2322 | V21: =ABS(Summary!F38) -> 830
A22: 42186 | B22: 31336.35 | C22: 2000.73 | D22: 9699.62 | E22: 19256 | F22: =(B22-B21)/B21 -> 0.030906112 | I22: House | J22: 0 | K22: 0 | L22: 0 | M22: 0 | N22: 0 | O22: 0 | P22: 0 | Q22: 3437.57 | R22: 3080.19 | S22: 5129.57 | T22: 14326.18 | U22: 3911.1 | V22: =ABS(Summary!F39) -> 1439.3
A23: 42217 | B23: 31108.32 | C23: 2000.45 | D23: 9537.07 | E23: 19570.8 | F23: =(B23-B22)/B22 -> -0.0072768526 | I23: School | J23: 0 | K23: 0 | L23: 0 | M23: 3657 | N23: 85.86 | O23: 2217 | P23: 0 | Q23: 0 | R23: 0 | S23: 0 | T23: 2421.8 | U23: 3036 | V23: =ABS(Summary!F40) -> 11681
A24: 42248 | B24: 31657.56 | C24: 2049.7 | D24: 9702.61 | E24: 19905.25 | F24: =(B24-B23)/B23 -> 0.017655727 | I24: Baby Sitter | J24: 0 | K24: 0 | L24: 0 | M24: 0 | N24: 0 | O24: 0 | P24: 0 | Q24: 0 | R24: 0 | S24: 0 | T24: 4334 | U24: 7446 | V24: =ABS(Summary!F41) -> 4801
A25: 42278 | B25: 33152.22 | C25: 2100.06 | D25: 10049.27 | E25: 20502.89 | F25: =(B25-B24)/B24 -> 0.047213367 | I25: Total | J25: =SUM(J4:J24) -> 35399.346 | K25: =SUM(K4:K23) -> 33810 | L25: =SUM(L4:L23) -> 33330.289 | M25: =SUM(M4:M23) -> 42343.479 | N25: =SUM(N4:N23) -> 48629.08 | O25: =SUM(O4:O23) -> 57314.43 | P25: =SUM(P4:P23) -> 61641.517 | Q25: =SUM(Q4:Q23) -> 66956.63 | R25: =SUM(R4:R23) -> 111005.54 | S25: =SUM(S4:S23) -> 133309.92 | T25: =SUM(T4:T24) -> 178085.15 | U25: =SUM(U4:U24) -> 160182.52 | V25: =SUM(V4:V23) -> 84544
A26: 42309 | B26: 34074.55 | C26: 2150.06 | D26: 10675.1 | E26: 21049.39 | F26: =(B26-B25)/B25 -> 0.027821063
A27: 42339 | B27: 34719.28 | C27: 2200.12 | D27: 10888.1 | E27: 21418.65 | F27: =(B27-B26)/B26 -> 0.01892116 | G27: =(B27-B16)/B16 -> 0.21423723 | I27: Category | J27: Total
A28: 42370 | B28: 35458.24 | C28: 2250.81 | D28: 11403.8 | E28: 21803.63 | F28: =(B28-B27)/B27 -> 0.021283852
A29: 42401 | B29: 35923.871 | C29: 2300.67 | D29: 11442.381 | E29: 22180.82 | F29: =(B29-B28)/B28 -> 0.013131814 | I29: Sum of 2014 | J29: Sum of 2015 | K29: Sum of 2016 | L29: Sum of 2017 | M29: Sum of 2018 | N29: Sum of 2019 | O29: Sum of 2020 | P29: Sum of 2021 | Q29: Sum of 2022 | R29: Sum of 2023 | S29: Sum of 2024 | T29: Sum of 2025 | U29: Sum of 2026
A30: 42430 | B30: 35940.411 | C30: 2350.87 | D30: 11029.601 | E30: 22559.94 | F30: =(B30-B29)/B29 -> 0.00046041809 | I30: 35399.346 | J30: 33810 | K30: 33330.289 | L30: 42343.479 | M30: 48629.08 | N30: 57314.43 | O30: 61641.517 | P30: 66956.63 | Q30: 111005.54 | R30: 133309.92 | S30: 178085.15 | T30: 160182.52 | U30: 5867
A31: 42461 | B31: 38992.73 | C31: 2400.64 | D31: 11581.9 | E31: 25010.19 | F31: =(B31-B30)/B30 -> 0.084927214
A32: 42491 | B32: 38568.28 | C32: 2450.66 | D32: 10608.47 | E32: 25509.15 | F32: =(B32-B31)/B31 -> -0.010885362
A33: 42522 | B33: 40042.39 | C33: 2500.3 | D33: 11550.75 | E33: 25991.34 | F33: =(B33-B32)/B32 -> 0.038220787
A34: 42552 | B34: 41991.17 | C34: 2550 | D34: 12479.63 | E34: 26961.54 | F34: =(B34-B33)/B33 -> 0.048667924
A35: 42583 | B35: 43010.93 | C35: 2600.99 | D35: 12659.63 | E35: 27750.31 | F35: =(B35-B34)/B34 -> 0.024285106
A36: 42614 | B36: 52337.87 | C36: 2650 | D36: 13404.63 | E36: 36283.24 | F36: =(B36-B35)/B35 -> 0.21685046
A37: 42644 | B37: 54547.5 | C37: 2700 | D37: 14589.63 | E37: 37257.87 | F37: =(B37-B36)/B36 -> 0.042218569
A38: 42675 | B38: 56251.08 | C38: 2750.96 | D38: 15614.63 | E38: 37885.49 | F38: =(B38-B37)/B37 -> 0.031231129
A39: 42705 | B39: 57734.43 | C39: 2800 | D39: 15801.63 | E39: 39132.8 | F39: =(B39-B38)/B38 -> 0.02637016 | G39: =(B39-B28)/B28 -> 0.62823733
A40: 42736 | B40: 59381.57 | C40: 2850.38 | D40: 16889.63 | E40: 39641.56 | F40: =(B40-B39)/B39 -> 0.028529597
A41: 42767 | B41: 63826.23 | C41: 2900.83 | D41: 16027.63 | E41: 44897.77 | F41: =(B41-B40)/B40 -> 0.074849149
A42: 42795 | B42: 67300.78 | C42: 2950.76 | D42: 18499.63 | E42: 45850.39 | F42: =(B42-B41)/B41 -> 0.05443765
...

Sheet Investment
B2: Investment*
C3: 2026 | D3: Invest | E3: Gain/ (Loss) | F3: FMV | G3: % Increase | H3: % Gained
B4: Etrade | C4: =Summary!Y4 -> 206508 | D4: =Summary!Z4 -> 0 | E4: =Summary!AA4 -> 7081 | F4: =Summary!AB4 -> 213589 | G4: =Summary!AC4 -> 0.034289229 | H4: =Summary!AD4 -> 0.034289229
B5: BC | C5: =Summary!Y5 -> 127109 | D5: =Summary!Z5 -> 5000 | E5: =Summary!AA5 -> 0 | F5: =Summary!AB5 -> 132109 | G5: =Summary!AC5 -> 0.039336318 | H5: =Summary!AD5 -> 0
B6: Roth IRA | C6: =Summary!Y6 -> 62955 | D6: =Summary!Z6 -> 1500 | E6: =Summary!AA6 -> 7439 | F6: =Summary!AB6 -> 71894 | G6: =Summary!AC6 -> 0.14199031 | H6: =Summary!AD6 -> 0.11541385
B7: TSP | C7: =Summary!Y7 -> 27298 | D7: =Summary!Z7 -> 0 | E7: =Summary!AA7 -> 0 | F7: =Summary!AB7 -> 27298 | G7: =Summary!AC7 -> 0 | H7: =Summary!AD7 -> 0
B8: UTMA | C8: =Summary!Y8 -> 3879 | D8: =Summary!Z8 -> 2600 | E8: =Summary!AA8 -> 641 | F8: =Summary!AB8 -> 7120 | G8: =Summary!AC8 -> 0.83552462 | H8: =Summary!AD8 -> 0.098935021
B9: 401K / Pension | C9: =Summary!Y9 -> 247061 | D9: =Summary!Z9 -> 0 | E9: =Summary!AA9 -> 42617 | F9: =Summary!AB9 -> 289678 | G9: =Summary!AC9 -> 0.17249586 | H9: =Summary!AD9 -> 0.17249586
B10: Chase/AMEX | C10: =Summary!Y10 -> 2944.3 | D10: =Summary!Z10 -> 0 | E10: =Summary!AA10 -> 1084.62 | F10: =Summary!AB10 -> 4028.92 | G10: =Summary!AC10 -> 0.36837958 | H10: =Summary!AD10 -> 0.36837958
B11: TOTAL | C11: =Summary!Y11 -> 677754.3 | D11: =Summary!Z11 -> 9100 | E11: =Summary!AA11 -> 58862.62 | F11: =Summary!AB11 -> 745716.92 | G11: =Summary!AC11 -> 0.10027619 | H11: =Summary!AD11 -> 0.085698845
C12: 2025 | D12: Invest | E12: Gain/ (Loss) | F12: FMV | G12: % Increase | H12: % Gained
B13: Etrade | C13: 88708 | D13: 38181 | E13: 79619 | F13: 206508 | G13: =(F13-C13)/C13 -> 1.3279524 | H13: =E13/(C13+D13) -> 0.62746968
B14: BC | C14: 104164 | D14: 14000 | E14: 8945 | F14: 127109 | G14: =(F14-C14)/C14 -> 0.22027764 | H14: =E14/(C14+D14) -> 0.075699875
B15: Roth IRA | C15: 48142 | D15: 7000 | E15: 7813 | F15: 62955 | G15: =(F15-C15)/C15 -> 0.30769391 | H15: =E15/(C15+D15) -> 0.14168873
B16: UTMA | C16: 3014 | D16: 400 | E16: 465 | F16: 3879 | G16: =(F16-C16)/C16 -> 0.28699403 | H16: =E16/(C16+D16) -> 0.13620387
B17: KPMG Pension | C17: 31601 | E17: 1580 | F17: 33181 | G17: =(F17-C17)/C17 -> 0.049998418 | H17: =E17/(C17+D17) -> 0.049998418
B18: 401K / Pension | C18: 191318 | E18: 49860 | F18: 241178 | G18: =(F18-C18)/C18 -> 0.26061322 | H18: =E18/(C18+D18) -> 0.26061322
B19: Chase/AMEX | C19: 1225.01 | E19: 1719.29 | F19: 2944.3 | G19: =(F19-C19)/C19 -> 1.4034906 | H19: =E19/(C19+D19) -> 1.4034906
B20: TOTAL | C20: 468172.01 | D20: 59581 | E20: 150001.29 | F20: 677754.3 | G20: =(F20-C20)/C20 -> 0.44766087 | H20: =E20/(C20+D20) -> 0.28422631
C21: 2024 | D21: Invest | E21: Gain/ (Loss) | F21: FMV | G21: % Increase | H21: % Gained
B22: Etrade | C22: 39026 | D22: 39211.76 | E22: 10471 | F22: 88708.76 | G22: =(F22-C22)/C22 -> 1.2730682 | H22: =E22/(C22+D22) -> 0.13383563
B23: BC | C23: 68968 | D23: 18212 | E23: 16984 | F23: 104164 | G23: =(F23-C23)/C23 -> 0.51032363 | H23: =E23/(C23+D23) -> 0.19481532
B24: Lending Club | C24: 35.5 | E24: -35.5 | F24: 0 | G24: =(F24-C24)/C24 -> -1 | H24: =E24/(C24+D24) -> -1
B25: Roth IRA | C25: 29214 | D25: 10100 | E25: 8828 | F25: 48142 | G25: =(F25-C25)/C25 -> 0.64790854 | H25: =E25/(C25+D25) -> 0.22455105
B26: TSP | C26: 27298 | F26: 27298 | G26: =(F26-C26)/C26 -> 0 | H26: =E26/(C26+D26) -> 0
B27: Card | C27: 5554.14 | E27: -5554.14 | F27: 0 | G27: =(F27-C27)/C27 -> -1 | H27: =E27/(C27+D27) -> -1
B28: UTMA | C28: 0 | D28: 3000 | E28: 14 | F28: 3014 | G28: =(F28-C28)/C28 -> #DIV/0! | H28: =E28/(C28+D28) -> 0.0046666667
B29: 401K / Pension | C29: 173715 | D29: -23895 | E29: 45801 | F29: 195621 | G29: =(F29-C29)/C29 -> 0.1261031 | H29: =E29/(C29+D29) -> 0.30570685
B30: Chase/AMEX | C30: 1119.06 | E30: 105.19 | F30: 1224.25 | G30: =(F30-C30)/C30 -> 0.093998534 | H30: =E30/(C30+D30) -> 0.093998534
B31: TOTAL | C31: 344929.7 | D31: 46628.76 | E31: 76613.55 | F31: 468172.01 | G31: =(F31-C31)/C31 -> 0.35729689 | H31: =E31/(C31+D31) -> 0.19566312
C32: 2023 | D32: Invest | E32: Gain/ (Loss) | F32: FMV | G32: % Increase | H32: % Gained
B33: Etrade | C33: 36511 | D33: 2000 | E33: 515 | F33: 39026 | G33: =(F33-C33)/C33 -> 0.06888335 | H33: =E33/(C33+D33) -> 0.013372803
B34: BC | C34: 65668 | D34: 3300 | F34: 68968 | G34: =(F34-C34)/C34 -> 0.050252787 | H34: =E34/(C34+D34) -> 0
B35: Lending Club | C35: 150.26 | D35: -24.07 | E35: -90.69 | F35: 35.5 | G35: =(F35-C35)/C35 -> -0.76374285 | H35: =E35/(C35+D35) -> -0.71867818
B36: Roth IRA | C36: 23787 | D36: 3600 | E36: 1827 | F36: 29214 | G36: =(F36-C36)/C36 -> 0.22814983 | H36: =E36/(C36+D36) -> 0.066710483
B37: TSP | C37: 27298 | F37: 27298 | G37: =(F37-C37)/C37 -> 0 | H37: =E37/(C37+D37) -> 0
B38: Card | C38: 5554.14 | F38: 5554.14 | G38: =(F38-C38)/C38 -> 0 | H38: =E38/(C38+D38) -> 0
B39: 401K / Pension | C39: 147725 | D39: 3876 | E39: 22114 | F39: 173715 | G39: =(F39-C39)/C39 -> 0.17593501 | H39: =E39/(C39+D39) -> 0.14586975
B40: Chase/AMEX | C40: 1752.18 | E40: -665.76 | F40: 1086.42 | G40: =(F40-C40)/C40 -> -0.37996096 | H40: =E40/(C40+D40) -> -0.37996096
B41: TOTAL | C41: 308445.58 | D41: 12751.93 | E41: 23699.55 | F41: 344897.06 | G41: =(F41-C41)/C41 -> 0.11817799 | H41: =E41/(C41+D41) -> 0.073784974
...

Sheet Summary
B2: 2026 | L2: Savings | X2: Investment*
B3: Month | C3: Net | D3: Budget | E3: Actual | F3: Variance | G3: Change | H3: Investment Earning | J3: Month | K3: Checkings | L3: School | M3: Buy | N3: House | O3: Car | P3: Travel | Q3: Kids | R3: Gifts | S3: Emergency | T3: Savings | U3: Investment* | V3: Total | W3: check | Y3: 2025 | Z3: Invest | AA3: Gain/ (Loss) | AB3: FMV | AC3: % Increase | AD3: % Gained
B4: 46023 | C4: =Jan!W73 -> 1083924.3 | D4: =K42 -> 13325 | E4: =L42 -> -13407 | F4: =D4+E4 -> -82 | G4: =C4-SUM(Jan!D3:W3) -> 32376.96 | H4: =Jan!AE21 -> 21346.6 | J4: =B4 -> 46023 | K4: =Jan!W72 -> 11100 | L4: =Jan!H65 -> 14645.08 | M4: =Jan!I65 -> 55015 | N4: =Jan!J65 -> 152796 | O4: =Jan!K65 -> 67208.71 | P4: =Jan!L65 -> 20985.75 | Q4: =Jan!M65 -> 30000.37 | R4: =Jan!N65 -> 4000 | S4: =Jan!O65 -> 25572.5 | T4: =SUM(L4:S4) -> 370223.41 | U4: =Jan!W71 -> 702600.9 | V4: =K4+T4+U4 -> 1083924.3 | W4: =C4-V4 -> 0 | X4: Etrade | Y4: =Jan!P3 -> 206508 | AA4: =Jan!AE15+Feb!AE15 -> 7081 | AB4: =SUM(Y4:AA4) -> 213589 | AC4: =(AB4-Y4)/Y4 -> 0.034289229 | AD4: =AA4/(Y4+Z4) -> 0.034289229
B5: 46054 | C5: =Feb!W61 -> 1098715.2 | D5: =N42 -> 11985 | E5: =O42 -> -12830.68 | F5: =D5+E5 -> -845.68 | G5: =C5-C4 -> 14790.93 | H5: =Feb!AE21 -> 5861.96 | J5: =B5 -> 46054 | K5: =Feb!W60 -> 11200 | L5: =Feb!H53 -> 14645.08 | M5: =Feb!I53 -> 57040 | N5: =Feb!J53 -> 153796 | O5: =Feb!K53 -> 69712.68 | P5: =Feb!L53 -> 20985.75 | Q5: =Feb!M53 -> 32000.37 | R5: =Feb!N53 -> 4000 | S5: =Feb!O53 -> 26572.5 | T5: =SUM(L5:S5) -> 378752.38 | U5: =Feb!W59 -> 708762.86 | V5: =K5+T5+U5 -> 1098715.2 | W5: =C5-V5 -> 0 | X5: BC | Y5: =Jan!Q3 -> 127109 | Z5: =Jan!AE7+'Apr '!AE7 -> 5000 | AB5: =SUM(Y5:AA5) -> 132109 | AC5: =(AB5-Y5)/Y5 -> 0.039336318 | AD5: =AA5/(Y5+Z5) -> 0
B6: 46082 | C6: =Mar!W77 -> 1081075.1 | D6: =Q42 -> 13555 | E6: =R42 -> -17117.97 | F6: =D6+E6 -> -3562.97 | G6: =C6-C5 -> -17640.12 | H6: =Mar!AE21 -> 474.72 | J6: =B6 -> 46082 | K6: =Mar!W76 -> 11300 | L6: =Mar!H69 -> 14845.08 | M6: =Mar!I69 -> 47065 | N6: =Mar!J69 -> 154796 | O6: =Mar!K69 -> 59712.68 | P6: =Mar!L69 -> 21245.91 | Q6: =Mar!M69 -> 32000.37 | R6: =Mar!N69 -> 4000 | S6: =Mar!O69 -> 26572.5 | T6: =SUM(L6:S6) -> 360237.54 | U6: =Mar!W75 -> 709537.58 | V6: =K6+T6+U6 -> 1081075.1 | W6: =C6-V6 -> 0 | X6: Roth IRA | Y6: =Jan!R3 -> 62955 | Z6: =Jan!AE9+Feb!AE8+Mar!AE8+'Apr '!AE8+'May '!AE8 -> 1500 | AA6: =Jan!AE18+'Apr '!AE17+'May '!AE17 -> 7439 | AB6: =SUM(Y6:AA6) -> 71894 | AC6: =(AB6-Y6)/Y6 -> 0.14199031 | AD6: =AA6/(Y6+Z6) -> 0.11541385
B7: 46113 | C7: ='Apr '!W68 -> 1106484 | D7: =T42 -> 21825 | E7: =U42 -> -25755.07 | F7: =D7+E7 -> -3930.07 | G7: =C7-C6 -> 25408.9 | H7: ='Apr '!AE20 -> 16551.9 | J7: =B7 -> 46113 | K7: ='Apr '!W67 -> 11400 | L7: ='Apr '!H60 -> 7939.08 | M7: ='Apr '!I60 -> 49090 | N7: ='Apr '!J60 -> 152868 | O7: ='Apr '!K60 -> 60578.68 | P7: ='Apr '!L60 -> 24245.91 | Q7: ='Apr '!M60 -> 32000.37 | R7: ='Apr '!N60 -> 4000 | S7: ='Apr '!O60 -> 33572.5 | T7: =SUM(L7:S7) -> 364294.54 | U7: ='Apr '!W66 -> 730789.48 | V7: =K7+T7+U7 -> 1106484 | W7: =C7-V7 -> 0 | X7: TSP | Y7: =Jan!U3 -> 27298 | AB7: =SUM(Y7:AA7) -> 27298 | AC7: =(AB7-Y7)/Y7 -> 0 | AD7: =AA7/(Y7+Z7) -> 0
B8: 46143 | C8: ='May '!W70 -> 1128693.4 | D8: =W42 -> 12855 | E8: =X42 -> -13700.14 | F8: =D8+E8 -> -845.14 | G8: =C8-C7 -> 22209.35 | H8: ='May '!AE21 -> 14627.44 | J8: =B8 -> 46143 | K8: ='May '!W69 -> 11500 | L8: ='May '!H62 -> 8939.08 | M8: ='May '!I62 -> 52071.91 | N8: ='May '!J62 -> 153868 | O8: ='May '!K62 -> 60778.68 | P8: ='May '!L62 -> 26245.91 | Q8: ='May '!M62 -> 32000.37 | R8: ='May '!N62 -> 4000 | S8: ='May '!O62 -> 33572.5 | T8: =SUM(L8:S8) -> 371476.45 | U8: ='May '!W68 -> 745716.92 | V8: =K8+T8+U8 -> 1128693.4 | W8: =C8-V8 -> 0 | X8: Riley (UTMA) | Y8: =Jan!S3 -> 3879 | Z8: =Jan!AE8+'Apr '!AE9 -> 2600 | AA8: =Jan!AE17+'May '!AE18 -> 641 | AB8: =SUM(Y8:AA8) -> 7120 | AC8: =(AB8-Y8)/Y8 -> 0.83552462 | AD8: =AA8/(Y8+Z8) -> 0.098935021
B9: 46174 | C9: ='Jun '!W53 -> 1122652.8 | D9: =Z42 -> 12775 | E9: =AA42 -> -6534.14 | F9: =D9+E9 -> 6240.86 | G9: =C9-C8 -> -6040.62 | H9: ='Jun '!AE18 -> 0 | J9: =B9 -> 46174 | K9: ='Jun '!W52 -> 11600 | L9: ='Jun '!H45 -> 8939.08 | M9: ='Jun '!I45 -> 44931.29 | N9: ='Jun '!J45 -> 154868 | O9: ='Jun '!K45 -> 60778.68 | P9: ='Jun '!L45 -> 26245.91 | Q9: ='Jun '!M45 -> 32000.37 | R9: ='Jun '!N45 -> 4000 | S9: ='Jun '!O45 -> 33572.5 | T9: =SUM(L9:S9) -> 365335.83 | U9: ='Jun '!W51 -> 745716.92 | V9: =K9+T9+U9 -> 1122652.8 | W9: =C9-V9 -> 0 | X9: 401K / Pension | Y9: =Jan!V3+Jan!T3 -> 247061 | AA9: =Jan!AE19+Feb!AE19+'Apr '!AE18+'May '!AE19 -> 42617 | AB9: =SUM(Y9:AA9) -> 289678 | AC9: =(AB9-Y9)/Y9 -> 0.17249586 | AD9: =AA9/(Y9+Z9) -> 0.17249586
B10: 46204 | C10: =Jul!W52 -> 0 | D10: =AC42 -> 14675 | E10: =AD42 -> 0 | F10: =D10+E10 -> 14675 | G10: =C10-C9 -> -1122652.8 | H10: =Jul!AE20 -> 0 | J10: =B10 -> 46204 | K10: =Jul!W51 -> 0 | L10: =Jul!H44 -> 0 | M10: =Jul!I44 -> 0 | N10: =Jul!J44 -> 0 | O10: =Jul!K44 -> 0 | P10: =Jul!L44 -> 0 | Q10: =Jul!M44 -> 0 | R10: =Jul!N44 -> 0 | S10: =Jul!O44 -> 0 | T10: =SUM(L10:S10) -> 0 | U10: =Jul!W50 -> 0 | V10: =K10+T10+U10 -> 0 | W10: =C10-V10 -> 0 | X10: Chase/AMEX | Y10: =Jan!W3 -> 2944.3 | AA10: =Jan!AE20+Feb!AE20+Mar!AE20+'Apr '!AE19+'May '!AE20 -> 1084.62 | AB10: =SUM(Y10:AA10) -> 4028.92 | AC10: =(AB10-Y10)/Y10 -> 0.36837958 | AD10: =AA10/(Y10+Z10) -> 0.36837958
B11: 46235 | C11: =Aug!W45 -> 0 | D11: =AF42 -> 12024.2 | E11: =AG42 -> 0 | F11: =D11+E11 -> 12024.2 | G11: =C11-C10 -> 0 | H11: =Aug!AE22 -> 0 | J11: =B11 -> 46235 | K11: =Aug!W44 -> 0 | L11: =Aug!H37 -> 0 | M11: =Aug!I37 -> 0 | N11: =Aug!J37 -> 0 | O11: =Aug!K37 -> 0 | P11: =Aug!L37 -> 0 | Q11: =Aug!M37 -> 0 | R11: =Aug!N37 -> 0 | S11: =Aug!O37 -> 0 | T11: =SUM(L11:S11) -> 0 | U11: =Aug!W43 -> 0 | V11: =K11+T11+U11 -> 0 | W11: =C11-V11 -> 0 | X11: TOTAL | Y11: =SUM(Y4:Y10) -> 677754.3 | Z11: =SUM(Z4:Z10) -> 9100 | AA11: =SUM(AA4:AA10) -> 58862.62 | AB11: =SUM(AB4:AB10) -> 745716.92 | AC11: =(AB11-Y11)/Y11 -> 0.10027619 | AD11: =AA11/(Y11+Z11) -> 0.085698845
B12: 46266 | C12: =Sep!W55 -> 0 | D12: =AI42 -> 11881.2 | E12: =AJ42 -> 0 | F12: =D12+E12 -> 11881.2 | G12: =C12-C11 -> 0 | H12: =Sep!AE22 -> 0 | J12: =B12 -> 46266 | K12: =Sep!W54 -> 0 | L12: =Sep!H44 -> 0 | M12: =Sep!I44 -> 0 | N12: =Sep!J44 -> 0 | O12: =Sep!K44 -> 0 | P12: =Sep!L44 -> 0 | Q12: =Sep!M44 -> 0 | R12: =Sep!N44 -> 0 | S12: =Sep!O44 -> 0 | T12: =SUM(L12:S12) -> 0 | U12: =Sep!W53 -> 0 | V12: =K12+T12+U12 -> 0 | W12: =C12-V12 -> 0 | AB12: =AB11-U9 -> 0
B13: 46296 | C13: =Oct!W59 -> 0 | D13: =AL42 -> 11381.2 | E13: =AM42 -> 0 | F13: =D13+E13 -> 11381.2 | G13: =C13-C12 -> 0 | H13: =Oct!AE22 -> 0 | J13: =B13 -> 46296 | K13: =Oct!W58 -> 0 | L13: =Oct!H48 -> 0 | M13: =Oct!I48 -> 0 | N13: =Oct!J48 -> 0 | O13: =Oct!K48 -> 0 | P13: =Oct!L48 -> 0 | Q13: =Oct!M48 -> 0 | R13: =Oct!N48 -> 0 | S13: =Oct!O48 -> 0 | T13: =SUM(L13:S13) -> 0 | U13: =Oct!W57 -> 0 | V13: =K13+T13+U13 -> 0 | W13: =C13-V13 -> 0
B14: 46327 | C14: =Nov!W47 -> 0 | D14: =AO42 -> 12031.2 | E14: =AP42 -> 0 | F14: =D14+E14 -> 12031.2 | G14: =C14-C13 -> 0 | H14: =Nov!AE22 -> 0 | J14: =B14 -> 46327 | K14: =Nov!W46 -> 0 | L14: =Nov!H36 -> 0 | M14: =Nov!I36 -> 0 | N14: =Nov!J36 -> 0 | O14: =Nov!K36 -> 0 | P14: =Nov!L36 -> 0 | Q14: =Nov!M36 -> 0 | R14: =Nov!N36 -> 0 | S14: =Nov!O36 -> 0 | T14: =SUM(L14:S14) -> 0 | U14: =Nov!W45 -> 0 | V14: =K14+T14+U14 -> 0 | W14: =C14-V14 -> 0
B15: 46357 | C15: =Dec!W50 -> 0 | D15: =AR42 -> 12631.2 | E15: =AS42 -> 0 | F15: =D15+E15 -> 12631.2 | G15: =C15-C14 -> 0 | H15: =Dec!AE18 -> 0 | J15: =B15 -> 46357 | K15: =Dec!W49 -> 0 | L15: =Dec!H39 -> 0 | M15: =Dec!I39 -> 0 | N15: =Dec!J39 -> 0 | O15: =Dec!K39 -> 0 | P15: =Dec!L39 -> 0 | Q15: =Dec!M39 -> 0 | R15: =Dec!N39 -> 0 | S15: =Dec!O39 -> 0 | T15: =SUM(L15:S15) -> 0 | U15: =Dec!W48 -> 0 | V15: =K15+T15+U15 -> 0 | W15: =C15-V15 -> 0
C16: TOTAL | D16: =SUM(D4:D15) -> 160944 | E16: =SUM(E4:E15) -> -89345 | F16: =SUM(F4:F15) -> 71599 | G16: =SUM(G4:G15) -> -1051547.4 | H16: =SUM(H4:H15) -> 58862.62
F17: Average | G17: =AVERAGE(G4:G15) -> -87628.946 | H17: =AVERAGE(H4:H15) -> 4905.2183
E19: 2026 | J19: 2026 | K19: =B4 -> 46023 | N19: =J5 -> 46054 | Q19: =J6 -> 46082 | T19: =J7 -> 46113 | W19: =J8 -> 46143 | Z19: =J9 -> 46174 | AC19: =J10 -> 46204 | AF19: =J11 -> 46235 | AI19: =J12 -> 46266 | AL19: =J13 -> 46296 | AO19: =J14 -> 46327 | AR19: =J15 -> 46357
D20: Category | E20: Budget | F20: Actual | G20: Variance | H20: % of Total | J20: Category | K20: Budget | L20: Actual | M20: Variance | N20: Budget | O20: Actual | P20: Variance | Q20: Budget | R20: Actual | S20: Variance | T20: Budget | U20: Actual | V20: Variance | W20: Budget | X20: Actual | Y20: Variance | Z20: Budget | AA20: Actual | AB20: Variance | AC20: Budget | AD20: Actual | AE20: Variance | AF20: Budget | AG20: Actual | AH20: Variance | AI20: Budget | AJ20: Actual | AK20: Variance | AL20: Budget | AM20: Actual | AN20: Variance | AO20: Budget | AP20: Actual | AQ20: Variance | AR20: Budget | AS20: Actual | AT20: Variance
D21: Cable | E21: =K21+N21+Q21+T21+W21+Z21+AC21+AF21+AI21+AL21+AO21+AR21 -> 4460 | F21: =L21+O21+R21+U21+X21+AA21+AD21+AG21+AJ21+AM21+AP21+AS21 -> -1782.99 | G21: =E21+F21 -> 2677.01 | H21: =ABS(F21)/E21 -> 0.39977354 | J21: Cable | K21: 350 | L21: =Jan!AA4 -> -326 | M21: =K21+L21 -> 24 | N21: 480 | O21: =Feb!AA4 -> -271 | P21: =N21+O21 -> 209 | Q21: 480 | R21: =Mar!AA4 -> -452 | S21: =Q21+R21 -> 28 | T21: 350 | U21: ='Apr '!AA4 -> -277 | V21: =T21+U21 -> 73 | W21: 350 | X21: ='May '!AA4 -> -381.99 | Y21: =W21+X21 -> -31.99 | Z21: 350 | AA21: ='Jun '!AA4 -> -75 | AB21: =Z21+AA21 -> 275 | AC21: 350 | AD21: =Jul!AA4 -> 0 | AE21: =AC21+AD21 -> 350 | AF21: 350 | AG21: =Aug!AA4 -> 0 | AH21: =AF21+AG21 -> 350 | AI21: 350 | AJ21: =Sep!AA4 -> 0 | AK21: =AI21+AJ21 -> 350 | AL21: 350 | AM21: =Oct!AA4 -> 0 | AN21: =AL21+AM21 -> 350 | AO21: 350 | AP21: =Nov!AA4 -> 0 | AQ21: =AO21+AP21 -> 350 | AR21: 350 | AS21: =Dec!AA5 -> 0 | AT21: =AR21+AS21 -> 350
D22: Car Insurance | E22: =K22+N22+Q22+T22+W22+Z22+AC22+AF22+AI22+AL22+AO22+AR22 -> 4020 | F22: =L22+O22+R22+U22+X22+AA22+AD22+AG22+AJ22+AM22+AP22+AS22 -> -1726.67 | G22: =E22+F22 -> 2293.33 | H22: =ABS(F22)/E22 -> 0.4295199 | J22: Car Insurance | K22: 335 | L22: =Jan!AA5 -> -342 | M22: =K22+L22 -> -7 | N22: 335 | O22: =Feb!AA5 -> -342 | P22: =N22+O22 -> -7 | Q22: 335 | R22: =Mar!AA5 -> -342 | S22: =Q22+R22 -> -7 | T22: 335 | U22: ='Apr '!AA5 -> -342 | V22: =T22+U22 -> -7 | W22: 335 | X22: ='May '!AA5 -> -358.67 | Y22: =W22+X22 -> -23.67 | Z22: 335 | AA22: ='Jun '!AA5 -> 0 | AB22: =Z22+AA22 -> 335 | AC22: 335 | AD22: =Jul!AA5 -> 0 | AE22: =AC22+AD22 -> 335 | AF22: 335 | AG22: =Aug!AA5 -> 0 | AH22: =AF22+AG22 -> 335 | AI22: 335 | AJ22: =Sep!AA5 -> 0 | AK22: =AI22+AJ22 -> 335 | AL22: 335 | AM22: =Oct!AA5 -> 0 | AN22: =AL22+AM22 -> 335 | AO22: 335 | AP22: =Nov!AA5 -> 0 | AQ22: =AO22+AP22 -> 335 | AR22: 335 | AS22: =Dec!AA6 -> 0 | AT22: =AR22+AS22 -> 335
D23: Cleaners | E23: =K23+N23+Q23+T23+W23+Z23+AC23+AF23+AI23+AL23+AO23+AR23 -> 160 | F23: =L23+O23+R23+U23+X23+AA23+AD23+AG23+AJ23+AM23+AP23+AS23 -> 0 | G23: =E23+F23 -> 160 | H23: =ABS(F23)/E23 -> 0 | J23: Cleaners | K23: 20 | L23: =Jan!AA6 -> 0 | M23: =K23+L23 -> 20 | N23: 20 | O23: =Feb!AA6 -> 0 | P23: =N23+O23 -> 20 | Q23: 20 | R23: =Mar!AA6 -> 0 | S23: =Q23+R23 -> 20 | T23: 20 | U23: ='Apr '!AA6 -> 0 | V23: =T23+U23 -> 20 | W23: 20 | X23: ='May '!AA6 -> 0 | Y23: =W23+X23 -> 20 | Z23: 20 | AA23: ='Jun '!AA6 -> 0 | AB23: =Z23+AA23 -> 20 | AC23: 20 | AD23: =Jul!AA6 -> 0 | AE23: =AC23+AD23 -> 20 | AF23: 20 | AG23: =Aug!AA6 -> 0 | AH23: =AF23+AG23 -> 20 | AI23: 0 | AJ23: =Sep!AA6 -> 0 | AK23: =AI23+AJ23 -> 0 | AL23: 0 | AM23: =Oct!AA6 -> 0 | AN23: =AL23+AM23 -> 0 | AO23: 0 | AP23: =Nov!AA6 -> 0 | AQ23: =AO23+AP23 -> 0 | AR23: 0 | AS23: =Dec!AA7 -> 0 | AT23: =AR23+AS23 -> 0
D24: Clothes | E24: =K24+N24+Q24+T24+W24+Z24+AC24+AF24+AI24+AL24+AO24+AR24 -> 1080 | F24: =L24+O24+R24+U24+X24+AA24+AD24+AG24+AJ24+AM24+AP24+AS24 -> -1827.19 | G24: =E24+F24 -> -747.19 | H24: =ABS(F24)/E24 -> 1.6918426 | J24: Clothes | K24: 300 | L24: =Jan!AA7 -> -353 | M24: =K24+L24 -> -53 | N24: 300 | O24: =Feb!AA7 -> -150 | P24: =N24+O24 -> 150 | Q24: 20 | R24: =Mar!AA7 -> -450 | S24: =Q24+R24 -> -430 | T24: 20 | U24: ='Apr '!AA7 -> -539 | V24: =T24+U24 -> -519 | W24: 300 | X24: ='May '!AA7 -> -262 | Y24: =W24+X24 -> 38 | Z24: 20 | AA24: ='Jun '!AA7 -> -73.19 | AB24: =Z24+AA24 -> -53.19 | AC24: 20 | AD24: =Jul!AA7 -> 0 | AE24: =AC24+AD24 -> 20 | AF24: 20 | AG24: =Aug!AA7 -> 0 | AH24: =AF24+AG24 -> 20 | AI24: 20 | AJ24: =Sep!AA7 -> 0 | AK24: =AI24+AJ24 -> 20 | AL24: 20 | AM24: =Oct!AA7 -> 0 | AN24: =AL24+AM24 -> 20 | AO24: 20 | AP24: =Nov!AA7 -> 0 | AQ24: =AO24+AP24 -> 20 | AR24: 20 | AS24: =Dec!AA8 -> 0 | AT24: =AR24+AS24 -> 20
D25: Utilities | E25: =K25+N25+Q25+T25+W25+Z25+AC25+AF25+AI25+AL25+AO25+AR25 -> 8400 | F25: =L25+O25+R25+U25+X25+AA25+AD25+AG25+AJ25+AM25+AP25+AS25 -> -3543.06 | G25: =E25+F25 -> 4856.94 | H25: =ABS(F25)/E25 -> 0.42179286 | J25: Utilities | K25: 700 | L25: =Jan!AA8 -> -492 | M25: =K25+L25 -> 208 | N25: 700 | O25: =Feb!AA8 -> -687.74 | P25: =N25+O25 -> 12.26 | Q25: 700 | R25: =Mar!AA8 -> -694.97 | S25: =Q25+R25 -> 5.03 | T25: 700 | U25: ='Apr '!AA8 -> -751.29 | V25: =T25+U25 -> -51.29 | W25: 700 | X25: ='May '!AA8 -> -642.06 | Y25: =W25+X25 -> 57.94 | Z25: 700 | AA25: ='Jun '!AA8 -> -275 | AB25: =Z25+AA25 -> 425 | AC25: 700 | AD25: =Jul!AA8 -> 0 | AE25: 650 | AF25: 700 | AG25: =Aug!AA8 -> 0 | AH25: =AF25+AG25 -> 700 | AI25: 700 | AJ25: =Sep!AA8 -> 0 | AK25: =AI25+AJ25 -> 700 | AL25: 700 | AM25: =Oct!AA8 -> 0 | AN25: =AL25+AM25 -> 700 | AO25: 700 | AP25: =Nov!AA8 -> 0 | AQ25: =AO25+AP25 -> 700 | AR25: 700 | AS25: =Dec!AA9 -> 0 | AT25: =AR25+AS25 -> 700
D26: Dining | E26: =K26+N26+Q26+T26+W26+Z26+AC26+AF26+AI26+AL26+AO26+AR26 -> 15600 | F26: =L26+O26+R26+U26+X26+AA26+AD26+AG26+AJ26+AM26+AP26+AS26 -> -8682.83 | G26: =E26+F26 -> 6917.17 | H26: =ABS(F26)/E26 -> 0.55659167 | J26: Dining | K26: 1300 | L26: =Jan!AA9 -> -1652 | M26: =K26+L26 -> -352 | N26: 1300 | O26: =Feb!AA9 -> -1495 | P26: =N26+O26 -> -195 | Q26: 1300 | R26: =Mar!AA9 -> -1959 | S26: =Q26+R26 -> -659 | T26: 1300 | U26: ='Apr '!AA9 -> -1631.13 | V26: =T26+U26 -> -331.13 | W26: 1300 | X26: ='May '!AA9 -> -1470.7 | Y26: =W26+X26 -> -170.7 | Z26: 1300 | AA26: ='Jun '!AA9 -> -475 | AB26: =Z26+AA26 -> 825 | AC26: 1300 | AD26: =Jul!AA9 -> 0 | AE26: =AC26+AD26 -> 1300 | AF26: 1300 | AG26: =Aug!AA9 -> 0 | AH26: =AF26+AG26 -> 1300 | AI26: 1300 | AJ26: =Sep!AA9 -> 0 | AK26: =AI26+AJ26 -> 1300 | AL26: 1300 | AM26: =Oct!AA9 -> 0 | AN26: =AL26+AM26 -> 1300 | AO26: 1300 | AP26: =Nov!AA9 -> 0 | AQ26: =AO26+AP26 -> 1300 | AR26: 1300 | AS26: =Dec!AA10 -> 0 | AT26: =AR26+AS26 -> 1300
D27: Entertainment | E27: =K27+N27+Q27+T27+W27+Z27+AC27+AF27+AI27+AL27+AO27+AR27 -> 1800 | F27: =L27+O27+R27+U27+X27+AA27+AD27+AG27+AJ27+AM27+AP27+AS27 -> -2548.38 | G27: =E27+F27 -> -748.38 | H27: =ABS(F27)/E27 -> 1.4157667 | J27: Entertainment | K27: 150 | L27: =Jan!AA10 -> -733 | M27: =K27+L27 -> -583 | N27: 150 | O27: =Feb!AA10 -> -435 | P27: =N27+O27 -> -285 | Q27: 150 | R27: =Mar!AA10 -> -853 | S27: =Q27+R27 -> -703 | T27: 150 | U27: ='Apr '!AA10 -> -347.38 | V27: =T27+U27 -> -197.38 | W27: 150 | X27: ='May '!AA10 -> -180 | Y27: =W27+X27 -> -30 | Z27: 150 | AA27: ='Jun '!AA10 -> 0 | AB27: =Z27+AA27 -> 150 | AC27: 150 | AD27: =Jul!AA10 -> 0 | AE27: =AC27+AD27 -> 150 | AF27: 150 | AG27: =Aug!AA10 -> 0 | AH27: =AF27+AG27 -> 150 | AI27: 150 | AJ27: =Sep!AA10 -> 0 | AK27: =AI27+AJ27 -> 150 | AL27: 150 | AM27: =Oct!AA10 -> 0 | AN27: =AL27+AM27 -> 150 | AO27: 150 | AP27: =Nov!AA10 -> 0 | AQ27: =AO27+AP27 -> 150 | AR27: 150 | AS27: =Dec!AA11 -> 0 | AT27: =AR27+AS27 -> 150
D28: Gas | E28: =K28+N28+Q28+T28+W28+Z28+AC28+AF28+AI28+AL28+AO28+AR28 -> 2400 | F28: =L28+O28+R28+U28+X28+AA28+AD28+AG28+AJ28+AM28+AP28+AS28 -> -1491.94 | G28: =E28+F28 -> 908.06 | H28: =ABS(F28)/E28 -> 0.62164167 | J28: Gas | K28: 200 | L28: =Jan!AA11 -> -160 | M28: =K28+L28 -> 40 | N28: 200 | O28: =Feb!AA11 -> -197.94 | P28: =N28+O28 -> 2.06 | Q28: 200 | R28: =Mar!AA11 -> -247 | S28: =Q28+R28 -> -47 | T28: 200 | U28: ='Apr '!AA11 -> -293 | V28: =T28+U28 -> -93 | W28: 200 | X28: ='May '!AA11 -> -481 | Y28: =W28+X28 -> -281 | Z28: 200 | AA28: ='Jun '!AA11 -> -113 | AB28: =Z28+AA28 -> 87 | AC28: 200 | AD28: =Jul!AA11 -> 0 | AE28: =AC28+AD28 -> 200 | AF28: 200 | AG28: =Aug!AA11 -> 0 | AH28: =AF28+AG28 -> 200 | AI28: 200 | AJ28: =Sep!AA11 -> 0 | AK28: =AI28+AJ28 -> 200 | AL28: 200 | AM28: =Oct!AA11 -> 0 | AN28: =AL28+AM28 -> 200 | AO28: 200 | AP28: =Nov!AA11 -> 0 | AQ28: =AO28+AP28 -> 200 | AR28: 200 | AS28: =Dec!AA12 -> 0 | AT28: =AR28+AS28 -> 200
D29: Gifts | E29: =K29+N29+Q29+T29+W29+Z29+AC29+AF29+AI29+AL29+AO29+AR29 -> 3650 | F29: =L29+O29+R29+U29+X29+AA29+AD29+AG29+AJ29+AM29+AP29+AS29 -> -2699.84 | G29: =E29+F29 -> 950.16 | H29: =ABS(F29)/E29 -> 0.73968219 | J29: Gifts | K29: 200 | L29: =Jan!AA12 -> -275 | M29: =K29+L29 -> -75 | N29: 200 | O29: =Feb!AA12 -> -423 | P29: =N29+O29 -> -223 | Q29: 200 | R29: =Mar!AA12 -> -915 | S29: =Q29+R29 -> -715 | T29: 200 | U29: ='Apr '!AA12 -> -496 | V29: =T29+U29 -> -296 | W29: 500 | X29: ='May '!AA12 -> -590.84 | Y29: =W29+X29 -> -90.84 | Z29: 500 | AA29: ='Jun '!AA12 -> 0 | AB29: =Z29+AA29 -> 500 | AC29: 200 | AD29: =Jul!AA12 -> 0 | AE29: =AC29+AD29 -> 200 | AF29: 50 | AG29: =Aug!AA12 -> 0 | AH29: =AF29+AG29 -> 50 | AI29: 50 | AJ29: =Sep!AA12 -> 0 | AK29: =AI29+AJ29 -> 50 | AL29: 50 | AM29: =Oct!AA12 -> 0 | AN29: =AL29+AM29 -> 50 | AO29: 500 | AP29: =Nov!AA12 -> 0 | AQ29: =AO29+AP29 -> 500 | AR29: 1000 | AS29: =Dec!AA13 -> 0 | AT29: =AR29+AS29 -> 1000
D30: Grocery | E30: =K30+N30+Q30+T30+W30+Z30+AC30+AF30+AI30+AL30+AO30+AR30 -> 12000 | F30: =L30+O30+R30+U30+X30+AA30+AD30+AG30+AJ30+AM30+AP30+AS30 -> -4870.26 | G30: =E30+F30 -> 7129.74 | H30: =ABS(F30)/E30 -> 0.405855 | J30: Grocery | K30: 1000 | L30: =Jan!AA13 -> -1314 | M30: =K30+L30 -> -314 | N30: 1000 | O30: =Feb!AA13 -> -777 | P30: =N30+O30 -> 223 | Q30: 1000 | R30: =Mar!AA13 -> -700 | S30: =Q30+R30 -> 300 | T30: 1000 | U30: ='Apr '!AA13 -> -630 | V30: =T30+U30 -> 370 | W30: 1000 | X30: ='May '!AA13 -> -1171.31 | Y30: =W30+X30 -> -171.31 | Z30: 1000 | AA30: ='Jun '!AA13 -> -277.95 | AB30: =Z30+AA30 -> 722.05 | AC30: 1000 | AD30: =Jul!AA13 -> 0 | AE30: =AC30+AD30 -> 1000 | AF30: 1000 | AG30: =Aug!AA13 -> 0 | AH30: =AF30+AG30 -> 1000 | AI30: 1000 | AJ30: =Sep!AA13 -> 0 | AK30: =AI30+AJ30 -> 1000 | AL30: 1000 | AM30: =Oct!AA13 -> 0 | AN30: =AL30+AM30 -> 1000 | AO30: 1000 | AP30: =Nov!AA13 -> 0 | AQ30: =AO30+AP30 -> 1000 | AR30: 1000 | AS30: =Dec!AA14 -> 0 | AT30: =AR30+AS30 -> 1000
D31: Gym | E31: =K31+N31+Q31+T31+W31+Z31+AC31+AF31+AI31+AL31+AO31+AR31 -> 2000 | F31: =L31+O31+R31+U31+X31+AA31+AD31+AG31+AJ31+AM31+AP31+AS31 -> -359 | G31: =E31+F31 -> 1641 | H31: =ABS(F31)/E31 -> 0.1795 | J31: Gym | K31: 100 | L31: =Jan!AA14 -> 0 | M31: =K31+L31 -> 100 | N31: 100 | O31: =Feb!AA14 -> 0 | P31: =N31+O31 -> 100 | Q31: 100 | R31: =Mar!AA14 -> 0 | S31: =Q31+R31 -> 100 | T31: 100 | U31: ='Apr '!AA14 -> -100 | V31: =T31+U31 -> 0 | W31: 200 | X31: ='May '!AA14 -> -259 | Y31: =W31+X31 -> -59 | Z31: 200 | AA31: ='Jun '!AA14 -> 0 | AB31: =Z31+AA31 -> 200 | AC31: 200 | AD31: =Jul!AA14 -> 0 | AE31: =AC31+AD31 -> 200 | AF31: 200 | AG31: =Aug!AA14 -> 0 | AH31: =AF31+AG31 -> 200 | AI31: 200 | AJ31: =Sep!AA14 -> 0 | AK31: =AI31+AJ31 -> 200 | AL31: 200 | AM31: =Oct!AA14 -> 0 | AN31: =AL31+AM31 -> 200 | AO31: 200 | AP31: =Nov!AA14 -> 0 | AQ31: =AO31+AP31 -> 200 | AR31: 200 | AS31: =Dec!AA15 -> 0 | AT31: =AR31+AS31 -> 200
D32: Loan | E32: =K32+N32+Q32+T32+W32+Z32+AC32+AF32+AI32+AL32+AO32+AR32 -> 0 | F32: =L32+O32+R32+U32+X32+AA32+AD32+AG32+AJ32+AM32+AP32+AS32 -> 0 | G32: =E32+F32 -> 0 | H32: 0 | J32: Loan | K32: 0 | L32: =Jan!AA15 -> 0 | M32: =K32+L32 -> 0 | N32: 0 | O32: =Feb!AA15 -> 0 | P32: =N32+O32 -> 0 | Q32: 0 | R32: =Mar!AA15 -> 0 | S32: =Q32+R32 -> 0 | T32: 0 | U32: ='Apr '!AA15 -> 0 | V32: =T32+U32 -> 0 | W32: 0 | X32: ='May '!AA15 -> 0 | Y32: =W32+X32 -> 0 | Z32: 0 | AA32: ='Jun '!AA15 -> 0 | AB32: =Z32+AA32 -> 0 | AC32: 0 | AD32: =Jul!AA15 -> 0 | AE32: =AC32+AD32 -> 0 | AF32: 0 | AG32: =Aug!AA15 -> 0 | AH32: =AF32+AG32 -> 0 | AI32: 0 | AJ32: =Sep!AA15 -> 0 | AK32: =AI32+AJ32 -> 0 | AL32: 0 | AM32: =Oct!AA15 -> 0 | AN32: =AL32+AM32 -> 0 | AO32: 0 | AP32: =Nov!AA15 -> 0 | AQ32: =AO32+AP32 -> 0 | AR32: 0 | AS32: =Dec!AA16 -> 0 | AT32: =AR32+AS32 -> 0
D33: Misc | E33: =K33+N33+Q33+T33+W33+Z33+AC33+AF33+AI33+AL33+AO33+AR33 -> 7600 | F33: =L33+O33+R33+U33+X33+AA33+AD33+AG33+AJ33+AM33+AP33+AS33 -> -2080 | G33: =E33+F33 -> 5520 | H33: =ABS(F33)/E33 -> 0.27368421 | J33: Misc | K33: 2000 | L33: =Jan!AA16 -> -287 | M33: =K33+L33 -> 1713 | N33: 500 | O33: =Feb!AA16 -> -300 | P33: =N33+O33 -> 200 | Q33: 500 | R33: =Mar!AA16 -> -457 | S33: =Q33+R33 -> 43 | T33: 500 | U33: ='Apr '!AA16 -> -906 | V33: =T33+U33 -> -406 | W33: 500 | X33: ='May '!AA16 -> -50 | Y33: =W33+X33 -> 450 | Z33: 500 | AA33: ='Jun '!AA16 -> -80 | AB33: =Z33+AA33 -> 420 | AC33: 500 | AD33: =Jul!AA16 -> 0 | AE33: =AC33+AD33 -> 500 | AF33: 500 | AG33: =Aug!AA16 -> 0 | AH33: =AF33+AG33 -> 500 | AI33: 500 | AJ33: =Sep!AA16 -> 0 | AK33: =AI33+AJ33 -> 500 | AL33: 500 | AM33: =Oct!AA16 -> 0 | AN33: =AL33+AM33 -> 500 | AO33: 500 | AP33: =Nov!AA16 -> 0 | AQ33: =AO33+AP33 -> 500 | AR33: 600 | AS33: =Dec!AA17 -> 0 | AT33: =AR33+AS33 -> 600
D34: Offering | E34: =K34+N34+Q34+T34+W34+Z34+AC34+AF34+AI34+AL34+AO34+AR34 -> 9600 | F34: =L34+O34+R34+U34+X34+AA34+AD34+AG34+AJ34+AM34+AP34+AS34 -> -4955.54 | G34: =E34+F34 -> 4644.46 | H34: =ABS(F34)/E34 -> 0.51620208 | J34: Offering | K34: 800 | L34: =Jan!AA17 -> -1264 | M34: =K34+L34 -> -464 | N34: 800 | O34: =Feb!AA17 -> -499 | P34: =N34+O34 -> 301 | Q34: 800 | R34: =Mar!AA17 -> -917 | S34: =Q34+R34 -> -117 | T34: 800 | U34: ='Apr '!AA17 -> -910.27 | V34: =T34+U34 -> -110.27 | W34: 800 | X34: ='May '!AA17 -> -909.27 | Y34: =W34+X34 -> -109.27 | Z34: 800 | AA34: ='Jun '!AA17 -> -456 | AB34: =Z34+AA34 -> 344 | AC34: 800 | AD34: =Jul!AA17 -> 0 | AE34: =AC34+AD34 -> 800 | AF34: 800 | AG34: =Aug!AA17 -> 0 | AH34: =AF34+AG34 -> 800 | AI34: 800 | AJ34: =Sep!AA17 -> 0 | AK34: =AI34+AJ34 -> 800 | AL34: 800 | AM34: =Oct!AA17 -> 0 | AN34: =AL34+AM34 -> 800 | AO34: 800 | AP34: =Nov!AA17 -> 0 | AQ34: =AO34+AP34 -> 800 | AR34: 800 | AS34: =Dec!AA18 -> 0 | AT34: =AR34+AS34 -> 800
D35: Rent | E35: =K35+N35+Q35+T35+W35+Z35+AC35+AF35+AI35+AL35+AO35+AR35 -> 49200 | F35: =L35+O35+R35+U35+X35+AA35+AD35+AG35+AJ35+AM35+AP35+AS35 -> -25304 | G35: =E35+F35 -> 23896 | H35: =ABS(F35)/E35 -> 0.51430894 | J35: Rent | K35: 4100 | L35: =Jan!AA18 -> -4134 | M35: =K35+L35 -> -34 | N35: 4100 | O35: =Feb!AA18 -> -4138 | P35: =N35+O35 -> -38 | Q35: 4100 | R35: =Mar!AA18 -> -4138 | S35: =Q35+R35 -> -38 | T35: 4100 | U35: ='Apr '!AA18 -> -4618 | V35: =T35+U35 -> -518 | W35: 4100 | X35: ='May '!AA18 -> -4138 | Y35: =W35+X35 -> -38 | Z35: 4100 | AA35: ='Jun '!AA18 -> -4138 | AB35: =Z35+AA35 -> -38 | AC35: 4100 | AD35: =Jul!AA18 -> 0 | AE35: =AC35+AD35 -> 4100 | AF35: 4100 | AG35: =Aug!AA18 -> 0 | AH35: =AF35+AG35 -> 4100 | AI35: 4100 | AJ35: =Sep!AA18 -> 0 | AK35: =AI35+AJ35 -> 4100 | AL35: 4100 | AM35: =Oct!AA18 -> 0 | AN35: =AL35+AM35 -> 4100 | AO35: 4100 | AP35: =Nov!AA18 -> 0 | AQ35: =AO35+AP35 -> 4100 | AR35: 4100 | AS35: =Dec!AA19 -> 0 | AT35: =AR35+AS35 -> 4100
D36: Travel | E36: =K36+N36+Q36+T36+W36+Z36+AC36+AF36+AI36+AL36+AO36+AR36 -> 5831 | F36: =L36+O36+R36+U36+X36+AA36+AD36+AG36+AJ36+AM36+AP36+AS36 -> -5677 | G36: =E36+F36 -> 154 | H36: =ABS(F36)/E36 -> 0.97358944 | J36: Travel | K36: 150 | L36: =Jan!AA19 -> 0 | M36: =K36+L36 -> 150 | N36: 0 | O36: =Feb!AA19 -> -1318 | P36: =N36+O36 -> -1318 | Q36: 1800 | R36: =Mar!AA19 -> -2709 | S36: =Q36+R36 -> -909 | T36: 0 | U36: ='Apr '!AA19 -> -1508 | V36: =T36+U36 -> -1508 | W36: 500 | X36: ='May '!AA19 -> -142 | Y36: =W36+X36 -> 358 | Z36: 500 | AA36: ='Jun '!AA19 -> 0 | AB36: =Z36+AA36 -> 500 | AC36: 2000 | AD36: =Jul!AA19 -> 0 | AE36: =AC36+AD36 -> 2000 | AF36: 176.2 | AG36: =Aug!AA19 -> 0 | AH36: =AF36+AG36 -> 176.2 | AI36: 176.2 | AJ36: =Sep!AA19 -> 0 | AK36: =AI36+AJ36 -> 176.2 | AL36: 176.2 | AM36: =Oct!AA19 -> 0 | AN36: =AL36+AM36 -> 176.2 | AO36: 176.2 | AP36: =Nov!AA19 -> 0 | AQ36: =AO36+AP36 -> 176.2 | AR36: 176.2 | AS36: =Dec!AA20 -> 0 | AT36: =AR36+AS36 -> 176.2
D37: Parents | E37: =K37+N37+Q37+T37+W37+Z37+AC37+AF37+AI37+AL37+AO37+AR37 -> 5700 | F37: =L37+O37+R37+U37+X37+AA37+AD37+AG37+AJ37+AM37+AP37+AS37 -> -3045 | G37: =E37+F37 -> 2655 | H37: =ABS(F37)/E37 -> 0.53421053 | J37: Parents | K37: 200 | L37: =Jan!AA20 -> -200 | M37: =K37+L37 -> 0 | N37: 500 | O37: =Feb!AA20 -> -500 | P37: =N37+O37 -> 0 | Q37: 500 | R37: =Mar!AA20 -> -500 | S37: =Q37+R37 -> 0 | T37: 500 | U37: ='Apr '!AA20 -> -500 | V37: =T37+U37 -> 0 | W37: 500 | X37: ='May '!AA20 -> -845 | Y37: =W37+X37 -> -345 | Z37: 500 | AA37: ='Jun '!AA20 -> -500 | AB37: =Z37+AA37 -> 0 | AC37: 500 | AD37: =Jul!AA20 -> 0 | AE37: =AC37+AD37 -> 500 | AF37: 500 | AG37: =Aug!AA20 -> 0 | AH37: =AF37+AG37 -> 500 | AI37: 500 | AJ37: =Sep!AA20 -> 0 | AK37: =AI37+AJ37 -> 500 | AL37: 500 | AM37: =Oct!AA20 -> 0 | AN37: =AL37+AM37 -> 500 | AO37: 500 | AP37: =Nov!AA20 -> 0 | AQ37: =AO37+AP37 -> 500 | AR37: 500 | AS37: =Dec!AA21 -> 0 | AT37: =AR37+AS37 -> 500
D38: Car | E38: =K38+N38+Q38+T38+W38+Z38+AC38+AF38+AI38+AL38+AO38+AR38 -> 3323 | F38: =L38+O38+R38+U38+X38+AA38+AD38+AG38+AJ38+AM38+AP38+AS38 -> -830 | G38: =E38+F38 -> 2493 | H38: =ABS(F38)/E38 -> 0.2497743 | J38: Car | K38: 200 | L38: =Jan!AA21 -> 0 | M38: =K38+L38 -> 200 | N38: 200 | O38: =Feb!AA21 -> 0 | P38: =N38+O38 -> 200 | Q38: 250 | R38: =Mar!AA21 -> 0 | S38: =Q38+R38 -> 250 | T38: 250 | U38: ='Apr '!AA21 -> -830 | V38: =T38+U38 -> -580 | W38: 0 | X38: ='May '!AA21 -> 0 | Y38: =W38+X38 -> 0 | Z38: 500 | AA38: ='Jun '!AA21 -> 0 | AB38: =Z38+AA38 -> 500 | AC38: 500 | AD38: =Jul!AA21 -> 0 | AE38: =AC38+AD38 -> 500 | AF38: 523 | AG38: =Aug!AA21 -> 0 | AH38: =AF38+AG38 -> 523 | AI38: 500 | AJ38: =Sep!AA21 -> 0 | AK38: =AI38+AJ38 -> 500 | AL38: 0 | AM38: =Oct!AA21 -> 0 | AN38: =AL38+AM38 -> 0 | AO38: 200 | AP38: =Nov!AA21 -> 0 | AQ38: =AO38+AP38 -> 200 | AR38: 200 | AS38: =Dec!AA22 -> 0 | AT38: =AR38+AS38 -> 200
D39: House | E39: =K39+N39+Q39+T39+W39+Z39+AC39+AF39+AI39+AL39+AO39+AR39 -> 3700 | F39: =L39+O39+R39+U39+X39+AA39+AD39+AG39+AJ39+AM39+AP39+AS39 -> -1439.3 | G39: =E39+F39 -> 2260.7 | H39: =ABS(F39)/E39 -> 0.389 | J39: House | K39: 200 | L39: =Jan!AA22 -> -425 | M39: =K39+L39 -> -225 | N39: 200 | O39: =Feb!AA22 -> -157 | P39: =N39+O39 -> 43 | Q39: 200 | R39: =Mar!AA22 -> -24 | S39: =Q39+R39 -> 176 | T39: 400 | U39: ='Apr '!AA22 -> -290 | V39: =T39+U39 -> 110 | W39: 500 | X39: ='May '!AA22 -> -508.3 | Y39: =W39+X39 -> -8.3 | Z39: 200 | AA39: ='Jun '!AA22 -> -35 | AB39: =Z39+AA39 -> 165 | AC39: 1000 | AD39: =Jul!AA22 -> 0 | AE39: =AC39+AD39 -> 1000 | AF39: 200 | AG39: =Aug!AA22 -> 0 | AH39: =AF39+AG39 -> 200 | AI39: 200 | AJ39: =Sep!AA22 -> 0 | AK39: =AI39+AJ39 -> 200 | AL39: 200 | AM39: =Oct!AA22 -> 0 | AN39: =AL39+AM39 -> 200 | AO39: 200 | AP39: =Nov!AA22 -> 0 | AQ39: =AO39+AP39 -> 200 | AR39: 200 | AS39: =Dec!AA23 -> 0 | AT39: =AR39+AS39 -> 200
D40: School | E40: =K40+N40+Q40+T40+W40+Z40+AC40+AF40+AI40+AL40+AO40+AR40 -> 10120 | F40: =L40+O40+R40+U40+X40+AA40+AD40+AG40+AJ40+AM40+AP40+AS40 -> -11681 | G40: =E40+F40 -> -1561 | H40: =ABS(F40)/E40 -> 1.154249 | J40: School | K40: 120 | L40: =Jan!AA23 -> -570 | M40: =K40+L40 -> -450 | N40: 0 | O40: =Feb!AA23 -> -260 | P40: =N40+O40 -> -260 | Q40: 0 | R40: =Mar!AA24 -> -880 | S40: =Q40+R40 -> -880 | T40: 10000 | U40: ='Apr '!AA23 -> -9906 | V40: =T40+U40 -> 94 | W40: 0 | X40: ='May '!AA23 -> -65 | Y40: =W40+X40 -> -65 | Z40: 0 | AA40: ='Jun '!AA23 -> 0 | AB40: =Z40+AA40 -> 0 | AC40: 0 | AD40: =Jul!AA23 -> 0 | AE40: =AC40+AD40 -> 0 | AF40: 0 | AG40: =Aug!AA23 -> 0 | AH40: =AF40+AG40 -> 0 | AI40: 0 | AJ40: =Sep!AA23 -> 0 | AK40: =AI40+AJ40 -> 0 | AL40: 0 | AM40: =Oct!AA23 -> 0 | AN40: =AL40+AM40 -> 0 | AO40: 0 | AP40: =Nov!AA23 -> 0 | AQ40: =AO40+AP40 -> 0 | AR40: 0 | AS40: =Dec!AA24 -> 0 | AT40: =AR40+AS40 -> 0
D41: Baby Sitter | E41: =K41+N41+Q41+T41+W41+Z41+AC41+AF41+AI41+AL41+AO41+AR41 -> 10300 | F41: =L41+O41+R41+U41+X41+AA41+AD41+AG41+AJ41+AM41+AP41+AS41 -> -4801 | G41: =E41+F41 -> 5499 | H41: =ABS(F41)/E41 -> 0.4661165 | J41: =D41 -> Baby Sitter | K41: 900 | L41: =Jan!AA24 -> -880 | M41: =K41+L41 -> 20 | N41: 900 | O41: =Feb!AA24 -> -880 | P41: =N41+O41 -> 20 | Q41: 900 | R41: =Mar!AA24 -> -880 | S41: =Q41+R41 -> 20 | T41: 900 | U41: ='Apr '!AA24 -> -880 | V41: =T41+U41 -> 20 | W41: 900 | X41: ='May '!AA24 -> -1245 | Y41: =W41+X41 -> -345 | Z41: 900 | AA41: ='Jun '!AA24 -> -36 | AB41: =Z41+AA41 -> 864 | AC41: 800 | AD41: =Jul!AA24 -> 0 | AE41: =AC41+AD41 -> 800 | AF41: 900 | AG41: =Aug!AA24 -> 0 | AH41: =AF41+AG41 -> 900 | AI41: 800 | AJ41: =Sep!AA24 -> 0 | AK41: =AI41+AJ41 -> 800 | AL41: 800 | AM41: =Oct!AA24 -> 0 | AN41: =AL41+AM41 -> 800 | AO41: 800 | AP41: =Nov!AA24 -> 0 | AQ41: =AO41+AP41 -> 800 | AR41: 800 | AS41: =Dec!AA25 -> 0 | AT41: =AR41+AS41 -> 800
D42: Total | E42: =SUM(E21:E41) -> 160944 | F42: =SUM(F21:F41) -> -89345 | G42: =SUM(G21:G40) -> 66100 | J42: Total | K42: =SUM(K21:K41) -> 13325 | L42: =SUM(L21:L41) -> -13407 | M42: =SUM(M21:M41) -> -82 | N42: =SUM(N21:N41) -> 11985 | O42: =SUM(O21:O41) -> -12830.68 | P42: =SUM(P21:P41) -> -845.68 | Q42: =SUM(Q21:Q41) -> 13555 | R42: =SUM(R21:R41) -> -17117.97 | ... AT42: =SUM(AT21:AT41) -> 12631.2
...

Sheet Children
A2: Riley | F2: Caleb
A3: Date | B3: From | C3: Description | D3: Transaction | F3: Date | G3: From | H3: Description | I3: Transaction
A4: 45603 | B4: Grandparents (Yoons) | C4: Dohl Gift | D4: 500 | F4: 46023 | G4: Granparents (Yoons and Kims) | H4: New Year's | I4: 200
A5: 45603 | B5: Granparents (Kims) | C5: Dohl Gift | D5: =3000-1250 -> 1750 | F5: 46090 | G5: Grandparents (Yoons) | H5: 100 Day | I5: 500
A6: 45603 | B6: Danny and Annie Roh | C6: Dohl Gift | D6: 150 | F6: 46090 | G6: Grandparents (Kims) | H6: 100 Day | I6: 500
A7: 45603 | B7: Stephanie and James | C7: Dohl Gift | D7: 100 | F7: 46090 | G7: Janet (Peony's friend) | H7: 100 Day | I7: 200
A8: 45603 | B8: Chaucer and Sarah | C8: Dohl Gift | D8: 100 | F8: 46143 | G8: Appa and Umma | H8: N/A | I8: 500
A9: 45603 | B9: Rina | C9: Dohl Gift | D9: 100
A10: 45603 | B10: Rinas parents | C10: Dohl Gift | D10: 300
A11: 45992 | B11: Grandparents (Yoons) | C11: 2year BDAY | D11: 400
A12: 46023 | B12: Granparents (Yoons and Kims) | C12: New Year's | D12: 200
A13: 46143 | B13: Appa and Umma | C13: N/A | D13: 500
B17: Total | D17: =SUM(D4:D14) -> 4100 | G17: Total | I17: =SUM(I4:I14) -> 1900
D19: =D17+I17 -> 6000

Sheet Dec
D1: Checking | F1: CC | H1: SAVINGS | P1: INVESTMENT | W1: CC
A2: Date | B2: Name | C2: Categorization | D2: PK | E2: Main | F2: Chase | G2: Chase | H2: School | I2: Buy | J2: House | K2: Car | L2: Travel | M2: Child | N2: Gifts | O2: Emergency | P2: E-Home | Q2: BC | R2: Roth IRA | S2: UTMA | T2: KPMG | U2: USAA | V2: 401K | W2: Chase | Y2: Budget to Actual | AD2: Activity
Y3: Category | Z3: Budget | AA3: Actual | AB3: Variance | AD3: Investment Activity
Y4: Cable | Z4: =Summary!AR21 -> 350 | AA4: =SUMIF($C$2:$C$37,Y4,$F$2:$F$37)+SUMIF($C$2:$C$37,Y4,$G$2:$G$37) -> 0 | AB4: =Z4+AA4 -> 350
Y5: Car Insurance | Z5: =Summary!AR22 -> 335 | AA5: =SUMIF($C$2:$C$37,Y5,$F$2:$F$37)+SUMIF($C$2:$C$37,Y5,$G$2:$G$37) -> 0 | AB5: =Z5+AA5 -> 335 | AD5: Invested Amount for month
Y6: Cleaners | Z6: =Summary!AR23 -> 0 | AA6: =SUMIF($C$2:$C$37,Y6,$F$2:$F$37)+SUMIF($C$2:$C$37,Y6,$G$2:$G$37) -> 0 | AB6: =Z6+AA6 -> 0 | AD6: Etrade
Y7: Clothes | Z7: =Summary!AR24 -> 20 | AA7: =SUMIF($C$2:$C$37,Y7,$F$2:$F$37)+SUMIF($C$2:$C$37,Y7,$G$2:$G$37) -> 0 | AB7: =Z7+AA7 -> 20 | AD7: Ecar
Y8: Utilities | Z8: =Summary!AR25 -> 700 | AA8: =SUMIF($C$2:$C$37,Y8,$F$2:$F$37)+SUMIF($C$2:$C$37,Y8,$G$2:$G$37) -> 0 | AB8: =Z8+AA8 -> 700 | AD8: CC
Y9: Dining | Z9: =Summary!AR26 -> 1300 | AA9: =SUMIF($C$2:$C$37,Y9,$F$2:$F$37)+SUMIF($C$2:$C$37,Y9,$G$2:$G$37) -> 0 | AB9: =Z9+AA9 -> 1300 | AD9: LC
Y10: Entertainment | Z10: =Summary!AR27 -> 150 | AA10: =SUMIF($C$2:$C$37,Y10,$F$2:$F$37)+SUMIF($C$2:$C$37,Y10,$G$2:$G$37) -> 0 | AB10: =Z10+AA10 -> 150 | AD10: Roth
Y11: Gas | Z11: =Summary!AR28 -> 200 | AA11: =SUMIF($C$2:$C$37,Y11,$F$2:$F$37)+SUMIF($C$2:$C$37,Y11,$G$2:$G$37) -> 0 | AB11: =Z11+AA11 -> 200 | AD11: 401K
Y12: Gifts | Z12: =Summary!AR29 -> 1000 | AA12: =SUMIF($C$2:$C$37,Y12,$F$2:$F$37)+SUMIF($C$2:$C$37,Y12,$G$2:$G$37) -> 0 | AB12: =Z12+AA12 -> 1000 | AD12: Total | AE12: =SUM(AE6:AE11) -> 0
Y13: Grocery | Z13: =Summary!AR30 -> 1000 | AA13: =SUMIF($C$2:$C$37,Y13,$F$2:$F$37)+SUMIF($C$2:$C$37,Y13,$G$2:$G$37) -> 0 | AB13: =Z13+AA13 -> 1000
Y14: Gym | Z14: =Summary!AR31 -> 200 | AA14: =SUMIF($C$2:$C$37,Y14,$F$2:$F$37)+SUMIF($C$2:$C$37,Y14,$G$2:$G$37) -> 0 | AB14: =Z14+AA14 -> 200 | AD14: Gain/Loss in Investment
Y15: Loan | Z15: =Summary!AR32 -> 0 | AA15: =SUMIF($C$2:$C$37,Y15,$F$2:$F$37)+SUMIF($C$2:$C$37,Y15,$G$2:$G$37) -> 0 | AB15: =Z15+AA15 -> 0 | AD15: Etrade
Y16: Misc | Z16: =Summary!AR33 -> 600 | AA16: =SUMIF($C$2:$C$37,Y16,$F$2:$F$37)+SUMIF($C$2:$C$37,Y16,$G$2:$G$37) -> 0 | AB16: =Z16+AA16 -> 600 | AD16: Ecar
Y17: Offering | Z17: =Summary!AR34 -> 800 | AA17: =SUMIF($C$2:$C$37,Y17,$F$2:$F$37)+SUMIF($C$2:$C$37,Y17,$G$2:$G$37) -> 0 | AB17: =Z17+AA17 -> 800 | AD17: BC
Y18: Rent | Z18: =Summary!AR35 -> 4100 | AA18: =SUMIF($C$2:$C$37,Y18,$F$2:$F$37)+SUMIF($C$2:$C$37,Y18,$G$2:$G$37) -> 0 | AB18: =Z18+AA18 -> 4100 | AD18: LC
Y19: Travel | Z19: =Summary!AR36 -> 176.2 | AA19: =SUMIF($C$2:$C$37,Y19,$F$2:$F$37)+SUMIF($C$2:$C$37,Y19,$G$2:$G$37) -> 0 | AB19: =Z19+AA19 -> 176.2 | AD19: Roth
Y20: Parents | Z20: =Summary!AR37 -> 500 | AA20: =SUMIF($C$2:$C$37,Y20,$F$2:$F$37)+SUMIF($C$2:$C$37,Y20,$G$2:$G$37) -> 0 | AB20: =Z20+AA20 -> 500 | AD20: 401K
Y21: Car | Z21: =Summary!AR38 -> 200 | AA21: =SUMIF($C$2:$C$37,Y21,$F$2:$F$37)+SUMIF($C$2:$C$37,Y21,$G$2:$G$37) -> 0 | AB21: =Z21+AA21 -> 200 | AD21: Chase & Amex
Y22: House | Z22: =Summary!AR39 -> 200 | AA22: =SUMIF($C$2:$C$37,Y22,$F$2:$F$37)+SUMIF($C$2:$C$37,Y22,$G$2:$G$37) -> 0 | AB22: =Z22+AA22 -> 200 | AD22: Total | AE22: =SUM(AE15:AE21) -> 0
Y23: School | Z23: =Summary!AR40 -> 0 | AA23: =SUMIF($C$2:$C$37,Y23,$F$2:$F$37)+SUMIF($C$2:$C$37,Y23,$G$2:$G$37) -> 0 | AB23: =Z23+AA23 -> 0
A39: Balance | D39: =SUM(D3:D38) -> 0 | E39: =SUM(E3:E38) -> 0 | F39: =SUM(F3:F38) -> 0 | G39: =SUM(G3:G38) -> 0 | H39: =SUM(H3:H38) -> 0 | I39: =SUM(I3:I38) -> 0 | J39: =SUM(J3:J38) -> 0 | K39: =SUM(K3:K38) -> 0 | ... W39: =SUM(W3:W38) -> 0 | Y39: Total | Z39: =SUM(Z4:Z37) -> 11831.2 | AA39: =SUM(AA4:AA37) -> 0 | AB39: =SUM(AB4:AB37) -> 11831.2
W44: =SUM(D39:W39) -> 0
Y46: PERCENTAGE
V47: Total Savings | W47: =SUM(H39:O39) -> 0 | Y47: =W47/W50 -> #DIV/0!
V48: Total Investments | W48: =SUM(P39:W39) -> 0 | Y48: =W48/W50 -> #DIV/0!
V49: Total Checking | W49: =E39+D39 -> 0 | Y49: =W49/W50 -> #DIV/0!
V50: TOTAL | W50: =SUM(W47:W49) -> 0
W52: =W50-W44 -> 0

Sheet Nov
D1: Checking | F1: CC | H1: SAVINGS | P1: INVESTMENT | W1: CC
A2: Date | B2: Name | C2: Categorization | D2: PK | E2: Main | F2: Chase | G2: Chase | H2: School | I2: Buy | J2: House | K2: Car | L2: Travel | M2: Child | N2: Gifts | O2: Emergency | P2: E-Home | Q2: BC | R2: Roth IRA | S2: UTMA | T2: KPMG | U2: USAA | V2: 401K | W2: Chase | Y2: Budget to Actual | AD2: Activity
Y3: Category | Z3: Budget | AA3: Actual | AB3: Variance | AD3: Investment Activity
Y4: Cable | Z4: =Summary!AO21 -> 350 | AA4: =SUMIF($C$2:$C$34,Y4,$F$2:$F$34)+SUMIF($C$2:$C$34,Y4,$G$2:$G$34) -> 0 | AB4: =Z4+AA4 -> 350
Y5: Car Insurance | Z5: =Summary!AO22 -> 335 | AA5: =SUMIF($C$2:$C$34,Y5,$F$2:$F$34)+SUMIF($C$2:$C$34,Y5,$G$2:$G$34) -> 0 | AB5: =Z5+AA5 -> 335 | AD5: Invested Amount for month
Y6: Cleaners | Z6: =Summary!AO23 -> 0 | AA6: =SUMIF($C$2:$C$34,Y6,$F$2:$F$34)+SUMIF($C$2:$C$34,Y6,$G$2:$G$34) -> 0 | AB6: =Z6+AA6 -> 0 | AD6: Etrade
Y7: Clothes | Z7: =Summary!AO24 -> 20 | AA7: =SUMIF($C$2:$C$34,Y7,$F$2:$F$34)+SUMIF($C$2:$C$34,Y7,$G$2:$G$34) -> 0 | AB7: =Z7+AA7 -> 20 | AD7: Ecar
Y8: Utilities | Z8: =Summary!AO25 -> 700 | AA8: =SUMIF($C$2:$C$34,Y8,$F$2:$F$34)+SUMIF($C$2:$C$34,Y8,$G$2:$G$34) -> 0 | AB8: =Z8+AA8 -> 700 | AD8: CC
Y9: Dining | Z9: =Summary!AO26 -> 1300 | AA9: =SUMIF($C$2:$C$34,Y9,$F$2:$F$34)+SUMIF($C$2:$C$34,Y9,$G$2:$G$34) -> 0 | AB9: =Z9+AA9 -> 1300 | AD9: LC
Y10: Entertainment | Z10: =Summary!AO27 -> 150 | AA10: =SUMIF($C$2:$C$34,Y10,$F$2:$F$34)+SUMIF($C$2:$C$34,Y10,$G$2:$G$34) -> 0 | AB10: =Z10+AA10 -> 150 | AD10: Roth
Y11: Gas | Z11: =Summary!AO28 -> 200 | AA11: =SUMIF($C$2:$C$34,Y11,$F$2:$F$34)+SUMIF($C$2:$C$34,Y11,$G$2:$G$34) -> 0 | AB11: =Z11+AA11 -> 200 | AD11: 401K
Y12: Gifts | Z12: =Summary!AO29 -> 500 | AA12: =SUMIF($C$2:$C$34,Y12,$F$2:$F$34)+SUMIF($C$2:$C$34,Y12,$G$2:$G$34) -> 0 | AB12: =Z12+AA12 -> 500 | AD12: Total | AE12: =SUM(AE6:AE11) -> 0
Y13: Grocery | Z13: =Summary!AO30 -> 1000 | AA13: =SUMIF($C$2:$C$34,Y13,$F$2:$F$34)+SUMIF($C$2:$C$34,Y13,$G$2:$G$34) -> 0 | AB13: =Z13+AA13 -> 1000
Y14: Gym | Z14: =Summary!AO31 -> 200 | AA14: =SUMIF($C$2:$C$34,Y14,$F$2:$F$34)+SUMIF($C$2:$C$34,Y14,$G$2:$G$34) -> 0 | AB14: =Z14+AA14 -> 200 | AD14: Gain/Loss in Investment
Y15: Loan | Z15: =Summary!AO32 -> 0 | AA15: =SUMIF($C$2:$C$34,Y15,$F$2:$F$34)+SUMIF($C$2:$C$34,Y15,$G$2:$G$34) -> 0 | AB15: =Z15+AA15 -> 0 | AD15: Etrade
Y16: Misc | Z16: =Summary!AO33 -> 500 | AA16: =SUMIF($C$2:$C$34,Y16,$F$2:$F$34)+SUMIF($C$2:$C$34,Y16,$G$2:$G$34) -> 0 | AB16: =Z16+AA16 -> 500 | AD16: Ecar
Y17: Offering | Z17: =Summary!AO34 -> 800 | AA17: =SUMIF($C$2:$C$34,Y17,$F$2:$F$34)+SUMIF($C$2:$C$34,Y17,$G$2:$G$34) -> 0 | AB17: =Z17+AA17 -> 800 | AD17: BC
Y18: Rent | Z18: =Summary!AO35 -> 4100 | AA18: =SUMIF($C$2:$C$34,Y18,$F$2:$F$34)+SUMIF($C$2:$C$34,Y18,$G$2:$G$34) -> 0 | AB18: =Z18+AA18 -> 4100 | AD18: LC
Y19: Travel | Z19: =Summary!AO36 -> 176.2 | AA19: =SUMIF($C$2:$C$34,Y19,$F$2:$F$34)+SUMIF($C$2:$C$34,Y19,$G$2:$G$34) -> 0 | AB19: =Z19+AA19 -> 176.2 | AD19: Roth
Y20: Parents | Z20: =Summary!AO37 -> 500 | AA20: =SUMIF($C$2:$C$34,Y20,$F$2:$F$34)+SUMIF($C$2:$C$34,Y20,$G$2:$G$34) -> 0 | AB20: =Z20+AA20 -> 500 | AD20: 401K
Y21: Car | Z21: =Summary!AO38 -> 200 | AA21: =SUMIF($C$2:$C$34,Y21,$F$2:$F$34)+SUMIF($C$2:$C$34,Y21,$G$2:$G$34) -> 0 | AB21: =Z21+AA21 -> 200 | AD21: Chase & Amex | AE21: =SUM(W35:W35) -> 0
Y22: House | Z22: =Summary!AO39 -> 200 | AA22: =SUMIF($C$2:$C$34,Y22,$F$2:$F$34)+SUMIF($C$2:$C$34,Y22,$G$2:$G$34) -> 0 | AB22: =Z22+AA22 -> 200 | AD22: Total | AE22: =SUM(AE15:AE21) -> 0
Y23: School | Z23: =Summary!AO40 -> 0 | AA23: =SUMIF($C$2:$C$34,Y23,$F$2:$F$34)+SUMIF($C$2:$C$34,Y23,$G$2:$G$34) -> 0 | AB23: =Z23+AA23 -> 0
Y24: Baby Sitter | Z24: =Summary!AR41 -> 800 | AA24: =SUMIF($C$2:$C$34,Y24,$F$2:$F$34)+SUMIF($C$2:$C$34,Y24,$G$2:$G$34) -> 0 | AB24: =Z24+AA24 -> 800
A36: Balance | D36: =SUM(D3:D35) -> 0 | E36: =SUM(E3:E35) -> 0 | F36: =SUM(F3:F35) -> 0 | G36: =SUM(G3:G35) -> 0 | H36: =SUM(H3:H35) -> 0 | I36: =SUM(I3:I35) -> 0 | J36: =SUM(J3:J35) -> 0 | K36: =SUM(K3:K35) -> 0 | ... W36: =SUM(W3:W35) -> 0 | Y36: Total | Z36: =SUM(Z4:Z34) -> 12031.2 | AA36: =SUM(AA4:AA34) -> 0 | AB36: =SUM(AB4:AB34) -> 12031.2
W41: =SUM(D36:W36) -> 0
Y43: PERCENTAGE
V44: Total Savings | W44: =SUM(H36:O36) -> 0 | Y44: =W44/W47 -> #DIV/0!
V45: Total Investments | W45: =SUM(P36:W36) -> 0 | Y45: =W45/W47 -> #DIV/0!
V46: Total Checking | W46: =E36+D36 -> 0 | Y46: =W46/W47 -> #DIV/0!
V47: TOTAL | W47: =SUM(W44:W46) -> 0
W49: =W47-W41 -> 0

Sheet Oct
D1: Checking | F1: CC | H1: SAVINGS | P1: INVESTMENT | W1: CC
A2: Date | B2: Name | C2: Categorization | D2: PK | E2: Main | F2: Chase | G2: Chase | H2: School | I2: Buy | J2: House | K2: Car | L2: Travel | M2: Child | N2: Gifts | O2: Emergency | P2: E-Home | Q2: BC | R2: Roth IRA | S2: UTMA | T2: KPMG | U2: USAA | V2: 401K | W2: Chase | Y2: Budget to Actual | AD2: Activity
Y3: Category | Z3: Budget | AA3: Actual | AB3: Variance | AD3: Investment Activity
Y4: Cable | Z4: =Summary!AL21 -> 350 | AA4: =SUMIF($C$2:$C$46,Y4,$F$2:$F$46)+SUMIF($C$2:$C$46,Y4,$G$2:$G$46) -> 0 | AB4: =Z4+AA4 -> 350
Y5: Car Insurance | Z5: =Summary!AL22 -> 335 | AA5: =SUMIF($C$2:$C$46,Y5,$F$2:$F$46)+SUMIF($C$2:$C$46,Y5,$G$2:$G$46) -> 0 | AB5: =Z5+AA5 -> 335 | AD5: Invested Amount for month
Y6: Cleaners | Z6: =Summary!AL23 -> 0 | AA6: =SUMIF($C$2:$C$46,Y6,$F$2:$F$46)+SUMIF($C$2:$C$46,Y6,$G$2:$G$46) -> 0 | AB6: =Z6+AA6 -> 0 | AD6: Etrade
Y7: Clothes | Z7: =Summary!AL24 -> 20 | AA7: =SUMIF($C$2:$C$46,Y7,$F$2:$F$46)+SUMIF($C$2:$C$46,Y7,$G$2:$G$46) -> 0 | AB7: =Z7+AA7 -> 20 | AD7: Ecar
Y8: Utilities | Z8: =Summary!AL25 -> 700 | AA8: =SUMIF($C$2:$C$46,Y8,$F$2:$F$46)+SUMIF($C$2:$C$46,Y8,$G$2:$G$46) -> 0 | AB8: =Z8+AA8 -> 700 | AD8: CC
Y9: Dining | Z9: =Summary!AL26 -> 1300 | AA9: =SUMIF($C$2:$C$46,Y9,$F$2:$F$46)+SUMIF($C$2:$C$46,Y9,$G$2:$G$46) -> 0 | AB9: =Z9+AA9 -> 1300 | AD9: LC
Y10: Entertainment | Z10: =Summary!AL27 -> 150 | AA10: =SUMIF($C$2:$C$46,Y10,$F$2:$F$46)+SUMIF($C$2:$C$46,Y10,$G$2:$G$46) -> 0 | AB10: =Z10+AA10 -> 150 | AD10: Roth
Y11: Gas | Z11: =Summary!AL28 -> 200 | AA11: =SUMIF($C$2:$C$46,Y11,$F$2:$F$46)+SUMIF($C$2:$C$46,Y11,$G$2:$G$46) -> 0 | AB11: =Z11+AA11 -> 200 | AD11: 401K
Y12: Gifts | Z12: =Summary!AL29 -> 50 | AA12: =SUMIF($C$2:$C$46,Y12,$F$2:$F$46)+SUMIF($C$2:$C$46,Y12,$G$2:$G$46) -> 0 | AB12: =Z12+AA12 -> 50 | AD12: Total | AE12: =SUM(AE6:AE11) -> 0
Y13: Grocery | Z13: =Summary!AL30 -> 1000 | AA13: =SUMIF($C$2:$C$46,Y13,$F$2:$F$46)+SUMIF($C$2:$C$46,Y13,$G$2:$G$46) -> 0 | AB13: =Z13+AA13 -> 1000
Y14: Gym | Z14: =Summary!AL31 -> 200 | AA14: =SUMIF($C$2:$C$46,Y14,$F$2:$F$46)+SUMIF($C$2:$C$46,Y14,$G$2:$G$46) -> 0 | AB14: =Z14+AA14 -> 200 | AD14: Gain/Loss in Investment
Y15: Loan | Z15: =Summary!AL32 -> 0 | AA15: =SUMIF($C$2:$C$46,Y15,$F$2:$F$46)+SUMIF($C$2:$C$46,Y15,$G$2:$G$46) -> 0 | AB15: =Z15+AA15 -> 0 | AD15: Etrade
Y16: Misc | Z16: =Summary!AL33 -> 500 | AA16: =SUMIF($C$2:$C$46,Y16,$F$2:$F$46)+SUMIF($C$2:$C$46,Y16,$G$2:$G$46) -> 0 | AB16: =Z16+AA16 -> 500 | AD16: Ecar
Y17: Offering | Z17: =Summary!AL34 -> 800 | AA17: =SUMIF($C$2:$C$46,Y17,$F$2:$F$46)+SUMIF($C$2:$C$46,Y17,$G$2:$G$46) -> 0 | AB17: =Z17+AA17 -> 800 | AD17: BC
Y18: Rent | Z18: =Summary!AL35 -> 4100 | AA18: =SUMIF($C$2:$C$46,Y18,$F$2:$F$46)+SUMIF($C$2:$C$46,Y18,$G$2:$G$46) -> 0 | AB18: =Z18+AA18 -> 4100 | AD18: LC
Y19: Travel | Z19: =Summary!AL36 -> 176.2 | AA19: =SUMIF($C$2:$C$46,Y19,$F$2:$F$46)+SUMIF($C$2:$C$46,Y19,$G$2:$G$46) -> 0 | AB19: =Z19+AA19 -> 176.2 | AD19: Roth
Y20: Parents | Z20: =Summary!AL37 -> 500 | AA20: =SUMIF($C$2:$C$46,Y20,$F$2:$F$46)+SUMIF($C$2:$C$46,Y20,$G$2:$G$46) -> 0 | AB20: =Z20+AA20 -> 500 | AD20: 401K
Y21: Car | Z21: =Summary!AL38 -> 0 | AA21: =SUMIF($C$2:$C$46,Y21,$F$2:$F$46)+SUMIF($C$2:$C$46,Y21,$G$2:$G$46) -> 0 | AB21: =Z21+AA21 -> 0 | AD21: Chase & Amex
Y22: House | Z22: =Summary!AL39 -> 200 | AA22: =SUMIF($C$2:$C$46,Y22,$F$2:$F$46)+SUMIF($C$2:$C$46,Y22,$G$2:$G$46) -> 0 | AB22: =Z22+AA22 -> 200 | AD22: Total | AE22: =SUM(AE15:AE21) -> 0
Y23: School | Z23: =Summary!AL40 -> 0 | AA23: =SUMIF($C$2:$C$46,Y23,$F$2:$F$46)+SUMIF($C$2:$C$46,Y23,$G$2:$G$46) -> 0 | AB23: =Z23+AA23 -> 0
A48: Balance | D48: =SUM(D3:D47) -> 0 | E48: =SUM(E3:E47) -> 0 | F48: =SUM(F3:F47) -> 0 | G48: =SUM(G3:G47) -> 0 | H48: =SUM(H3:H47) -> 0 | I48: =SUM(I3:I47) -> 0 | J48: =SUM(J3:J47) -> 0 | K48: =SUM(K3:K47) -> 0 | ... V48: =SUM(V3:V47) -> 0 | Y48: Total | Z48: =SUM(Z4:Z46) -> 10581.2 | AA48: =SUM(AA4:AA46) -> 0 | AB48: =SUM(AB4:AB46) -> 10581.2
W53: =SUM(D48:V48) -> 0
Y55: PERCENTAGE
V56: Total Savings | W56: =SUM(H48:O48) -> 0 | Y56: =W56/W59 -> #DIV/0!
V57: Total Investments | W57: =SUM(P48:V48) -> 0 | Y57: =W57/W59 -> #DIV/0!
V58: Total Checking | W58: =E48+D48 -> 0 | Y58: =W58/W59 -> #DIV/0!
V59: TOTAL | W59: =SUM(W56:W58) -> 0
W61: =W59-W53 -> 0

Sheet Sep
D1: Checking | F1: CC | H1: SAVINGS | P1: INVESTMENT | W1: CC
A2: Date | B2: Name | C2: Categorization | D2: PK | E2: Main | F2: Chase | G2: Chase | H2: School | I2: Buy | J2: House | K2: Car | L2: Travel | M2: Child | N2: Gifts | O2: Emergency | P2: E-Home | Q2: BC | R2: Roth IRA | S2: UTMA | T2: KPMG | U2: USAA | V2: 401K | W2: Chase | Y2: Budget to Actual | AD2: Activity
Y3: Category | Z3: Budget | AA3: Actual | AB3: Variance | AD3: Investment Activity
Y4: Cable | Z4: =Summary!AI21 -> 350 | AA4: =SUMIF($C$2:$C$42,Y4,$F$2:$F$42)+SUMIF($C$2:$C$42,Y4,$G$2:$G$42) -> 0 | AB4: =Z4+AA4 -> 350
Y5: Car Insurance | Z5: =Summary!AI22 -> 335 | AA5: =SUMIF($C$2:$C$42,Y5,$F$2:$F$42)+SUMIF($C$2:$C$42,Y5,$G$2:$G$42) -> 0 | AB5: =Z5+AA5 -> 335 | AD5: Invested Amount for month
Y6: Cleaners | Z6: =Summary!AI23 -> 0 | AA6: =SUMIF($C$2:$C$42,Y6,$F$2:$F$42)+SUMIF($C$2:$C$42,Y6,$G$2:$G$42) -> 0 | AB6: =Z6+AA6 -> 0 | AD6: Etrade
Y7: Clothes | Z7: =Summary!AI24 -> 20 | AA7: =SUMIF($C$2:$C$42,Y7,$F$2:$F$42)+SUMIF($C$2:$C$42,Y7,$G$2:$G$42) -> 0 | AB7: =Z7+AA7 -> 20 | AD7: Ecar
